Workbook

Sheet Dashboard
A1: Name des Hundes | B1: Cara
A2: Gewicht | B2: 27
A3: Zielgewicht | B3: 27
A4: Altersgruppe | B4: > 7 Jahre
A5: Soffwechselgewicht | B5: =B2^0.75 -> 11.844666
A6: Verdaulichkeit Protein | B6: Gekocht
A7: Energiebedarf | B7: Normal
A13: Futtermittel | B13: Menge in g
A14: Pferd Fleisch, roh | B14: 400
A15: Zucchini gedünstet | B15: 30
A16: Karotte/Möhre, gekocht | B16: 90
A17: Reis poliert, roh | B17: 40
A18: Anchovisöl Kochen für Hunde | B18: 6
A19: Hanföl | B19: 6
A20: Kürbis Hokkaido (C. maxima) gekocht | B20: 30
A21: Pferdefett, ausgelassen | B21: 5
A22: Napfcheck Novomineral Balance | B22: 4
A23: Napfcheck Novomineral Sensitive | B23: 5
B36: Soll Max | C36: M/Z Maximum | D36: =IF($C$36="", "", _xlfn.XLOOKUP("M/Z Maximum", Bedarfswerte!$A:$A, Bedarfswerte!C:C, "")) -> 0 | E36: =IF($C$36="", "", _xlfn.XLOOKUP("M/Z Maximum", Bedarfswerte!$A:$A, Bedarfswerte!D:D, "")) -> 0 | F36: =IF($C$36="", "", _xlfn.XLOOKUP("M/Z Maximum", Bedarfswerte!$A:$A, Bedarfswerte!E:E, "")) -> 0 | G36: =IF($C$36="", "", _xlfn.XLOOKUP("M/Z Maximum", Bedarfswerte!$A:$A, Bedarfswerte!F:F, "")) -> 0 | H36: =IF($C$36="", "", _xlfn.XLOOKUP("M/Z Maximum", Bedarfswerte!$A:$A, Bedarfswerte!G:G, "")) -> 0 | I36: =IF($C$36="", "", _xlfn.XLOOKUP("M/Z Maximum", Bedarfswerte!$A:$A, Bedarfswerte!H:H, "")) -> 0 | J36: =IF($C$36="", "", _xlfn.XLOOKUP("M/Z Maximum", Bedarfswerte!$A:$A, Bedarfswerte!I:I, "")) -> 0 | K36: =IF($C$36="", "", _xlfn.XLOOKUP("M/Z Maximum", Bedarfswerte!$A:$A, Bedarfswerte!J:J, "")) -> 0 | L36: =IF($C$36="", "", _xlfn.XLOOKUP("M/Z Maximum", Bedarfswerte!$A:$A, Bedarfswerte!K:K, "")) -> 0 | M36: =IF($C$36="", "", _xlfn.XLOOKUP("M/Z Maximum", Bedarfswerte!$A:$A, Bedarfswerte!L:L, "")) -> 0 | N36: =IF($C$36="", "", _xlfn.XLOOKUP("M/Z Maximum", Bedarfswerte!$A:$A, Bedarfswerte!M:M, "")) -> 0 | O36: =IF($C$36="", "", _xlfn.XLOOKUP("M/Z Maximum", Bedarfswerte!$A:$A, Bedarfswerte!N:N, "")) -> 0 | P36: =IF($C$36="", "", _xlfn.XLOOKUP("M/Z Maximum", Bedarfswerte!$A:$A, Bedarfswerte!O:O, "")) -> 0 | Q36: =IF($C$36="", "", _xlfn.XLOOKUP("M/Z Maximum", Bedarfswerte!$A:$A, Bedarfswerte!P:P, "")) -> 0 | R36: =IF($C$36="", "", _xlfn.XLOOKUP("M/Z Maximum", Bedarfswerte!$A:$A, Bedarfswerte!Q:Q, "")) -> 54000 | S36: =IF($C$36="", "", _xlfn.XLOOKUP("M/Z Maximum", Bedarfswerte!$A:$A, Bedarfswerte!R:R, "")) -> 0 | T36: =IF($C$36="", "", _xlfn.XLOOKUP("M/Z Maximum", Bedarfswerte!$A:$A, Bedarfswerte!S:S, "")) -> 0 | U36: =IF($C$36="", "", _xlfn.XLOOKUP("M/Z Maximum", Bedarfswerte!$A:$A, Bedarfswerte!T:T, "")) -> 0 | V36: =IF($C$36="", "", _xlfn.XLOOKUP("M/Z Maximum", Bedarfswerte!$A:$A, Bedarfswerte!U:U, "")) -> 135 | W36: =IF($C$36="", "", _xlfn.XLOOKUP("M/Z Maximum", Bedarfswerte!$A:$A, Bedarfswerte!V:V, "")) -> 0 | X36: =IF($C$36="", "", _xlfn.XLOOKUP("M/Z Maximum", Bedarfswerte!$A:$A, Bedarfswerte!W:W, "")) -> 3.51 | Y36: =IF($C$36="", "", _xlfn.XLOOKUP("M/Z Maximum", Bedarfswerte!$A:$A, Bedarfswerte!X:X, "")) -> 0 | Z36: =IF($C$36="", "", _xlfn.XLOOKUP("M/Z Maximum", Bedarfswerte!$A:$A, Bedarfswerte!Y:Y, "")) -> 0 | AA36: =IF($C$36="", "", _xlfn.XLOOKUP("M/Z Maximum", Bedarfswerte!$A:$A, Bedarfswerte!Z:Z, "")) -> 33.75 | AB36: =IF($C$36="", "", _xlfn.XLOOKUP("M/Z Maximum", Bedarfswerte!$A:$A, Bedarfswerte!AA:AA, "")) -> 297 | AC36: =IF($C$36="", "", _xlfn.XLOOKUP("M/Z Maximum", Bedarfswerte!$A:$A, Bedarfswerte!AB:AB, "")) -> 121500 | AD36: =IF($C$36="", "", _xlfn.XLOOKUP("M/Z Maximum", Bedarfswerte!$A:$A, Bedarfswerte!AC:AC, "")) -> 0 | AE36: =IF($C$36="", "", _xlfn.XLOOKUP("M/Z Maximum", Bedarfswerte!$A:$A, Bedarfswerte!AD:AD, "")) -> 0 | AF36: =IF($C$36="", "", _xlfn.XLOOKUP("M/Z Maximum", Bedarfswerte!$A:$A, Bedarfswerte!AE:AE, "")) -> 0 | AG36: =IF($C$36="", "", _xlfn.XLOOKUP("M/Z Maximum", Bedarfswerte!$A:$A, Bedarfswerte!AF:AF, "")) -> 0 | AH36: =IF($C$36="", "", _xlfn.XLOOKUP("M/Z Maximum", Bedarfswerte!$A:$A, Bedarfswerte!AG:AG, "")) -> 0 | AI36: =IF($C$36="", "", _xlfn.XLOOKUP("M/Z Maximum", Bedarfswerte!$A:$A, Bedarfswerte!AH:AH, "")) -> 0 | AJ36: =IF($C$36="", "", _xlfn.XLOOKUP("M/Z Maximum", Bedarfswerte!$A:$A, Bedarfswerte!AI:AI, "")) -> 0 | AK36: =IF($C$36="", "", _xlfn.XLOOKUP("M/Z Maximum", Bedarfswerte!$A:$A, Bedarfswerte!AJ:AJ, "")) -> 0 | AL36: =IF($C$36="", "", _xlfn.XLOOKUP("M/Z Maximum", Bedarfswerte!$A:$A, Bedarfswerte!AK:AK, "")) -> 0 | AM36: =IF($C$36="", "", _xlfn.XLOOKUP("M/Z Maximum", Bedarfswerte!$A:$A, Bedarfswerte!AL:AL, "")) -> 0 | AN36: =IF($C$36="", "", _xlfn.XLOOKUP("M/Z Maximum", Bedarfswerte!$A:$A, Bedarfswerte!AM:AM, "")) -> 0 | AO36: =IF($C$36="", "", _xlfn.XLOOKUP("M/Z Maximum", Bedarfswerte!$A:$A, Bedarfswerte!AN:AN, "")) -> 2430 | AP36: =IF($C$36="", "", _xlfn.XLOOKUP("M/Z Maximum", Bedarfswerte!$A:$A, Bedarfswerte!AO:AO, "")) -> 1620 | AQ36: =IF($C$36="", "", _xlfn.XLOOKUP("M/Z Maximum", Bedarfswerte!$A:$A, Bedarfswerte!AP:AP, "")) -> 0 | AR36: =IF($C$36="", "", _xlfn.XLOOKUP("M/Z Maximum", Bedarfswerte!$A:$A, Bedarfswerte!AQ:AQ, "")) -> 0 | AS36: =IF($C$36="", "", _xlfn.XLOOKUP("M/Z Maximum", Bedarfswerte!$A:$A, Bedarfswerte!AR:AR, "")) -> 0 | AT36: =IF($C$36="", "", _xlfn.XLOOKUP("M/Z Maximum", Bedarfswerte!$A:$A, Bedarfswerte!AS:AS, "")) -> 0 | AU36: =IF($C$36="", "", _xlfn.XLOOKUP("M/Z Maximum", Bedarfswerte!$A:$A, Bedarfswerte!AT:AT, "")) -> 0 | AV36: =IF($C$36="", "", _xlfn.XLOOKUP("M/Z Maximum", Bedarfswerte!$A:$A, Bedarfswerte!AU:AU, "")) -> 0 | AW36: =IF($C$36="", "", _xlfn.XLOOKUP("M/Z Maximum", Bedarfswerte!$A:$A, Bedarfswerte!AV:AV, "")) -> 0 | AX36: =IF($C$36="", "", _xlfn.XLOOKUP("M/Z Maximum", Bedarfswerte!$A:$A, Bedarfswerte!AW:AW, "")) -> 1350 | AY36: =IF($C$36="", "", _xlfn.XLOOKUP("M/Z Maximum", Bedarfswerte!$A:$A, Bedarfswerte!AX:AX, "")) -> 405000 | AZ36: =IF($C$36="", "", _xlfn.XLOOKUP("M/Z Maximum", Bedarfswerte!$A:$A, Bedarfswerte!AY:AY, "")) -> 443.28358
B37: Soll Min. | C37: M/Z Minimum | D37: =IF($C$37="", "", _xlfn.XLOOKUP("M/Z Minimum", Bedarfswerte!$A:$A, Bedarfswerte!C:C, "")) -> 0 | E37: =IF($C$37="", "", _xlfn.XLOOKUP("M/Z Minimum", Bedarfswerte!$A:$A, Bedarfswerte!D:D, "")) -> 0 | F37: =IF($C$37="", "", _xlfn.XLOOKUP("M/Z Minimum", Bedarfswerte!$A:$A, Bedarfswerte!E:E, "")) -> 33 | G37: =IF($C$37="", "", _xlfn.XLOOKUP("M/Z Minimum", Bedarfswerte!$A:$A, Bedarfswerte!F:F, "")) -> 29.7 | H37: =IF($C$37="", "", _xlfn.XLOOKUP("M/Z Minimum", Bedarfswerte!$A:$A, Bedarfswerte!G:G, "")) -> 27 | I37: =IF($C$37="", "", _xlfn.XLOOKUP("M/Z Minimum", Bedarfswerte!$A:$A, Bedarfswerte!H:H, "")) -> 0 | J37: =IF($C$37="", "", _xlfn.XLOOKUP("M/Z Minimum", Bedarfswerte!$A:$A, Bedarfswerte!I:I, "")) -> 0 | K37: =IF($C$37="", "", _xlfn.XLOOKUP("M/Z Minimum", Bedarfswerte!$A:$A, Bedarfswerte!J:J, "")) -> 0 | L37: =IF($C$37="", "", _xlfn.XLOOKUP("M/Z Minimum", Bedarfswerte!$A:$A, Bedarfswerte!K:K, "")) -> 0 | M37: =IF($C$37="", "", _xlfn.XLOOKUP("M/Z Minimum", Bedarfswerte!$A:$A, Bedarfswerte!L:L, "")) -> 0 | N37: =IF($C$37="", "", _xlfn.XLOOKUP("M/Z Minimum", Bedarfswerte!$A:$A, Bedarfswerte!M:M, "")) -> 1674 | O37: =IF($C$37="", "", _xlfn.XLOOKUP("M/Z Minimum", Bedarfswerte!$A:$A, Bedarfswerte!N:N, "")) -> 1242 | P37: =IF($C$37="", "", _xlfn.XLOOKUP("M/Z Minimum", Bedarfswerte!$A:$A, Bedarfswerte!O:O, "")) -> 270 | Q37: =IF($C$37="", "", _xlfn.XLOOKUP("M/Z Minimum", Bedarfswerte!$A:$A, Bedarfswerte!P:P, "")) -> 540 | R37: =IF($C$37="", "", _xlfn.XLOOKUP("M/Z Minimum", Bedarfswerte!$A:$A, Bedarfswerte!Q:Q, "")) -> 0 | S37: =IF($C$37="", "", _xlfn.XLOOKUP("M/Z Minimum", Bedarfswerte!$A:$A, Bedarfswerte!R:R, "")) -> 0 | T37: =IF($C$37="", "", _xlfn.XLOOKUP("M/Z Minimum", Bedarfswerte!$A:$A, Bedarfswerte!S:S, "")) -> 13.5 | U37: =IF($C$37="", "", _xlfn.XLOOKUP("M/Z Minimum", Bedarfswerte!$A:$A, Bedarfswerte!T:T, "")) -> 0 | V37: =IF($C$37="", "", _xlfn.XLOOKUP("M/Z Minimum", Bedarfswerte!$A:$A, Bedarfswerte!U:U, "")) -> 0 | W37: =IF($C$37="", "", _xlfn.XLOOKUP("M/Z Minimum", Bedarfswerte!$A:$A, Bedarfswerte!V:V, "")) -> 0 | X37: =IF($C$37="", "", _xlfn.XLOOKUP("M/Z Minimum", Bedarfswerte!$A:$A, Bedarfswerte!W:W, "")) -> 0.27 | Y37: =IF($C$37="", "", _xlfn.XLOOKUP("M/Z Minimum", Bedarfswerte!$A:$A, Bedarfswerte!X:X, "")) -> 351 | Z37: =IF($C$37="", "", _xlfn.XLOOKUP("M/Z Minimum", Bedarfswerte!$A:$A, Bedarfswerte!Y:Y, "")) -> 0 | AA37: =IF($C$37="", "", _xlfn.XLOOKUP("M/Z Minimum", Bedarfswerte!$A:$A, Bedarfswerte!Z:Z, "")) -> 0 | AB37: =IF($C$37="", "", _xlfn.XLOOKUP("M/Z Minimum", Bedarfswerte!$A:$A, Bedarfswerte!AA:AA, "")) -> 0 | AC37: =IF($C$37="", "", _xlfn.XLOOKUP("M/Z Minimum", Bedarfswerte!$A:$A, Bedarfswerte!AB:AB, "")) -> 0 | AD37: =IF($C$37="", "", _xlfn.XLOOKUP("M/Z Minimum", Bedarfswerte!$A:$A, Bedarfswerte!AC:AC, "")) -> 0 | AE37: =IF($C$37="", "", _xlfn.XLOOKUP("M/Z Minimum", Bedarfswerte!$A:$A, Bedarfswerte!AD:AD, "")) -> 0 | AF37: =IF($C$37="", "", _xlfn.XLOOKUP("M/Z Minimum", Bedarfswerte!$A:$A, Bedarfswerte!AE:AE, "")) -> 0 | AG37: =IF($C$37="", "", _xlfn.XLOOKUP("M/Z Minimum", Bedarfswerte!$A:$A, Bedarfswerte!AF:AF, "")) -> 0 | AH37: =IF($C$37="", "", _xlfn.XLOOKUP("M/Z Minimum", Bedarfswerte!$A:$A, Bedarfswerte!AG:AG, "")) -> 0 | AI37: =IF($C$37="", "", _xlfn.XLOOKUP("M/Z Minimum", Bedarfswerte!$A:$A, Bedarfswerte!AH:AH, "")) -> 0 | AJ37: =IF($C$37="", "", _xlfn.XLOOKUP("M/Z Minimum", Bedarfswerte!$A:$A, Bedarfswerte!AI:AI, "")) -> 0 | AK37: =IF($C$37="", "", _xlfn.XLOOKUP("M/Z Minimum", Bedarfswerte!$A:$A, Bedarfswerte!AJ:AJ, "")) -> 0 | AL37: =IF($C$37="", "", _xlfn.XLOOKUP("M/Z Minimum", Bedarfswerte!$A:$A, Bedarfswerte!AK:AK, "")) -> 0 | AM37: =IF($C$37="", "", _xlfn.XLOOKUP("M/Z Minimum", Bedarfswerte!$A:$A, Bedarfswerte!AL:AL, "")) -> 0 | AN37: =IF($C$37="", "", _xlfn.XLOOKUP("M/Z Minimum", Bedarfswerte!$A:$A, Bedarfswerte!AM:AM, "")) -> 0 | AO37: =IF($C$37="", "", _xlfn.XLOOKUP("M/Z Minimum", Bedarfswerte!$A:$A, Bedarfswerte!AN:AN, "")) -> 486 | AP37: =IF($C$37="", "", _xlfn.XLOOKUP("M/Z Minimum", Bedarfswerte!$A:$A, Bedarfswerte!AO:AO, "")) -> 324 | AQ37: =IF($C$37="", "", _xlfn.XLOOKUP("M/Z Minimum", Bedarfswerte!$A:$A, Bedarfswerte!AP:AP, "")) -> 0 | AR37: =IF($C$37="", "", _xlfn.XLOOKUP("M/Z Minimum", Bedarfswerte!$A:$A, Bedarfswerte!AQ:AQ, "")) -> 1350 | AS37: =IF($C$37="", "", _xlfn.XLOOKUP("M/Z Minimum", Bedarfswerte!$A:$A, Bedarfswerte!AR:AR, "")) -> 1512 | AT37: =IF($C$37="", "", _xlfn.XLOOKUP("M/Z Minimum", Bedarfswerte!$A:$A, Bedarfswerte!AS:AS, "")) -> 837 | AU37: =IF($C$37="", "", _xlfn.XLOOKUP("M/Z Minimum", Bedarfswerte!$A:$A, Bedarfswerte!AT:AT, "")) -> 864 | AV37: =IF($C$37="", "", _xlfn.XLOOKUP("M/Z Minimum", Bedarfswerte!$A:$A, Bedarfswerte!AU:AU, "")) -> 1512 | AW37: =IF($C$37="", "", _xlfn.XLOOKUP("M/Z Minimum", Bedarfswerte!$A:$A, Bedarfswerte!AV:AV, "")) -> 1512 | AX37: =IF($C$37="", "", _xlfn.XLOOKUP("M/Z Minimum", Bedarfswerte!$A:$A, Bedarfswerte!AW:AW, "")) -> 0 | AY37: =IF($C$37="", "", _xlfn.XLOOKUP("M/Z Minimum", Bedarfswerte!$A:$A, Bedarfswerte!AX:AX, "")) -> 0 | AZ37: =IF($C$37="", "", _xlfn.XLOOKUP("M/Z Minimum", Bedarfswerte!$A:$A, Bedarfswerte!AY:AY, "")) -> 0
B38: Soll Empf. | C38: M/Z Empfehlung | D38: =IF($C$38="", "", _xlfn.XLOOKUP("M/Z Empfehlung", Bedarfswerte!$A:$A, Bedarfswerte!C:C, "") * IF($B$7="kastriert (- 15 %)", 0.85, IF($B$7="kastriert (- 20 %)", 0.8, IF($B$7="Übergewicht (- 30 %)", 0.7, 1)))) -> 1188.9676 | E38: =IF($C$38="", "", _xlfn.XLOOKUP("M/Z Empfehlung", Bedarfswerte!$A:$A, Bedarfswerte!D:D, "") * IF($B$7="kastriert (- 15 %)", 0.85, IF($B$7="kastriert (- 20 %)", 0.8, IF($B$7="Übergewicht (- 30 %)", 0.7, 1)))) -> 4.9747598 | F38: =IF($C$38="", "", _xlfn.XLOOKUP("M/Z Empfehlung", Bedarfswerte!$A:$A, Bedarfswerte!E:E, "")) -> 66 | G38: =IF($C$38="", "", _xlfn.XLOOKUP("M/Z Empfehlung", Bedarfswerte!$A:$A, Bedarfswerte!F:F, "")) -> 59.4 | H38: =IF($C$38="", "", _xlfn.XLOOKUP("M/Z Empfehlung", Bedarfswerte!$A:$A, Bedarfswerte!G:G, "")) -> 0 | I38: =IF($C$38="", "", _xlfn.XLOOKUP("M/Z Empfehlung", Bedarfswerte!$A:$A, Bedarfswerte!H:H, "")) -> 0 | J38: =IF($C$38="", "", _xlfn.XLOOKUP("M/Z Empfehlung", Bedarfswerte!$A:$A, Bedarfswerte!I:I, "")) -> 0 | K38: =IF($C$38="", "", _xlfn.XLOOKUP("M/Z Empfehlung", Bedarfswerte!$A:$A, Bedarfswerte!J:J, "")) -> 0 | L38: =IF($C$38="", "", _xlfn.XLOOKUP("M/Z Empfehlung", Bedarfswerte!$A:$A, Bedarfswerte!K:K, "")) -> 0 | M38: =IF($C$38="", "", _xlfn.XLOOKUP("M/Z Empfehlung", Bedarfswerte!$A:$A, Bedarfswerte!L:L, "")) -> 0 | N38: =IF($C$38="", "", _xlfn.XLOOKUP("M/Z Empfehlung", Bedarfswerte!$A:$A, Bedarfswerte!M:M, "")) -> 2160 | O38: =IF($C$38="", "", _xlfn.XLOOKUP("M/Z Empfehlung", Bedarfswerte!$A:$A, Bedarfswerte!N:N, "")) -> 1620 | P38: =IF($C$38="", "", _xlfn.XLOOKUP("M/Z Empfehlung", Bedarfswerte!$A:$A, Bedarfswerte!O:O, "")) -> 324 | Q38: =IF($C$38="", "", _xlfn.XLOOKUP("M/Z Empfehlung", Bedarfswerte!$A:$A, Bedarfswerte!P:P, "")) -> 1350 | R38: =IF($C$38="", "", _xlfn.XLOOKUP("M/Z Empfehlung", Bedarfswerte!$A:$A, Bedarfswerte!Q:Q, "")) -> 1485 | S38: =IF($C$38="", "", _xlfn.XLOOKUP("M/Z Empfehlung", Bedarfswerte!$A:$A, Bedarfswerte!R:R, "")) -> 2025 | T38: =IF($C$38="", "", _xlfn.XLOOKUP("M/Z Empfehlung", Bedarfswerte!$A:$A, Bedarfswerte!S:S, "")) -> 37.8 | U38: =IF($C$38="", "", _xlfn.XLOOKUP("M/Z Empfehlung", Bedarfswerte!$A:$A, Bedarfswerte!T:T, "")) -> 24.3 | V38: =IF($C$38="", "", _xlfn.XLOOKUP("M/Z Empfehlung", Bedarfswerte!$A:$A, Bedarfswerte!U:U, "")) -> 67.5 | W38: =IF($C$38="", "", _xlfn.XLOOKUP("M/Z Empfehlung", Bedarfswerte!$A:$A, Bedarfswerte!V:V, "")) -> 2.7 | X38: =IF($C$38="", "", _xlfn.XLOOKUP("M/Z Empfehlung", Bedarfswerte!$A:$A, Bedarfswerte!W:W, "")) -> 1.89 | Y38: =IF($C$38="", "", _xlfn.XLOOKUP("M/Z Empfehlung", Bedarfswerte!$A:$A, Bedarfswerte!X:X, "")) -> 405 | Z38: =IF($C$38="", "", _xlfn.XLOOKUP("M/Z Empfehlung", Bedarfswerte!$A:$A, Bedarfswerte!Y:Y, "")) -> 0 | AA38: =IF($C$38="", "", _xlfn.XLOOKUP("M/Z Empfehlung", Bedarfswerte!$A:$A, Bedarfswerte!Z:Z, "")) -> 6.75 | AB38: =IF($C$38="", "", _xlfn.XLOOKUP("M/Z Empfehlung", Bedarfswerte!$A:$A, Bedarfswerte!AA:AA, "")) -> 13.5 | AC38: =IF($C$38="", "", _xlfn.XLOOKUP("M/Z Empfehlung", Bedarfswerte!$A:$A, Bedarfswerte!AB:AB, "")) -> 607.5 | AD38: =IF($C$38="", "", _xlfn.XLOOKUP("M/Z Empfehlung", Bedarfswerte!$A:$A, Bedarfswerte!AC:AC, "")) -> 540 | AE38: =IF($C$38="", "", _xlfn.XLOOKUP("M/Z Empfehlung", Bedarfswerte!$A:$A, Bedarfswerte!AD:AD, "")) -> 1350 | AF38: =IF($C$38="", "", _xlfn.XLOOKUP("M/Z Empfehlung", Bedarfswerte!$A:$A, Bedarfswerte!AE:AE, "")) -> 5400 | AG38: =IF($C$38="", "", _xlfn.XLOOKUP("M/Z Empfehlung", Bedarfswerte!$A:$A, Bedarfswerte!AF:AF, "")) -> 540 | AH38: =IF($C$38="", "", _xlfn.XLOOKUP("M/Z Empfehlung", Bedarfswerte!$A:$A, Bedarfswerte!AG:AG, "")) -> 13.5 | AI38: =IF($C$38="", "", _xlfn.XLOOKUP("M/Z Empfehlung", Bedarfswerte!$A:$A, Bedarfswerte!AH:AH, "")) -> 0 | AJ38: =IF($C$38="", "", _xlfn.XLOOKUP("M/Z Empfehlung", Bedarfswerte!$A:$A, Bedarfswerte!AI:AI, "")) -> 0 | AK38: =IF($C$38="", "", _xlfn.XLOOKUP("M/Z Empfehlung", Bedarfswerte!$A:$A, Bedarfswerte!AJ:AJ, "")) -> 108 | AL38: =IF($C$38="", "", _xlfn.XLOOKUP("M/Z Empfehlung", Bedarfswerte!$A:$A, Bedarfswerte!AK:AK, "")) -> 54 | AM38: =IF($C$38="", "", _xlfn.XLOOKUP("M/Z Empfehlung", Bedarfswerte!$A:$A, Bedarfswerte!AL:AL, "")) -> 0 | AN38: =IF($C$38="", "", _xlfn.XLOOKUP("M/Z Empfehlung", Bedarfswerte!$A:$A, Bedarfswerte!AM:AM, "")) -> 0 | AO38: =IF($C$38="", "", _xlfn.XLOOKUP("M/Z Empfehlung", Bedarfswerte!$A:$A, Bedarfswerte!AN:AN, "")) -> 1215 | AP38: =IF($C$38="", "", _xlfn.XLOOKUP("M/Z Empfehlung", Bedarfswerte!$A:$A, Bedarfswerte!AO:AO, "")) -> 810 | AQ38: =IF($C$38="", "", _xlfn.XLOOKUP("M/Z Empfehlung", Bedarfswerte!$A:$A, Bedarfswerte!AP:AP, "")) -> 0 | AR38: =IF($C$38="", "", _xlfn.XLOOKUP("M/Z Empfehlung", Bedarfswerte!$A:$A, Bedarfswerte!AQ:AQ, "")) -> 4050 | AS38: =IF($C$38="", "", _xlfn.XLOOKUP("M/Z Empfehlung", Bedarfswerte!$A:$A, Bedarfswerte!AR:AR, "")) -> 1512 | AT38: =IF($C$38="", "", _xlfn.XLOOKUP("M/Z Empfehlung", Bedarfswerte!$A:$A, Bedarfswerte!AS:AS, "")) -> 1377 | AU38: =IF($C$38="", "", _xlfn.XLOOKUP("M/Z Empfehlung", Bedarfswerte!$A:$A, Bedarfswerte!AT:AT, "")) -> 864 | AV38: =IF($C$38="", "", _xlfn.XLOOKUP("M/Z Empfehlung", Bedarfswerte!$A:$A, Bedarfswerte!AU:AU, "")) -> 1836 | AW38: =IF($C$38="", "", _xlfn.XLOOKUP("M/Z Empfehlung", Bedarfswerte!$A:$A, Bedarfswerte!AV:AV, "")) -> 2052 | AX38: =IF($C$38="", "", _xlfn.XLOOKUP("M/Z Empfehlung", Bedarfswerte!$A:$A, Bedarfswerte!AW:AW, "")) -> 270 | AY38: =IF($C$38="", "", _xlfn.XLOOKUP("M/Z Empfehlung", Bedarfswerte!$A:$A, Bedarfswerte!AX:AX, "")) -> 2025 | AZ38: =IF($C$38="", "", _xlfn.XLOOKUP("M/Z Empfehlung", Bedarfswerte!$A:$A, Bedarfswerte!AY:AY, "")) -> 20.149254
B39: Ist | D39: =SUM(D41:D61) -> 764.19 | E39: =SUM(E41:E61) -> 3.1974477 | F39: =SUM(F41:F61) -> 86.8664 | G39: =SUM(G41:G61) -> 73.83644 | H39: =SUM(H41:H61) -> 28.2716 | I39: =SUM(I41:I61) -> 54.9424 | J39: =SUM(J41:J61) -> 0.07 | K39: =SUM(K41:K61) -> 5.074 | ... R39: =SUM(R41:R61) -> 2023.9007 | T39: =SUM(T41:T61) -> 28.27163 | U39: =SUM(U41:U61) -> 44.079651 | V39: =SUM(V41:V61) -> 0 | W39: =SUM(W41:W61) -> 3.5416719 | X39: =SUM(X41:X61) -> 1.9278738 | Y39: =SUM(Y41:Y61) -> 509.4686 | AA39: =SUM(AA41:AA61) -> 7.85 | AB39: =SUM(AB41:AB61) -> 60.5045 | AC39: =SUM(AC41:AC61) -> 965.4484 | AD39: =SUM(AD41:AD61) -> 1799.9 | AE39: =SUM(AE41:AE61) -> 3238.9 | AF39: =SUM(AF41:AF61) -> 24573.1 | AG39: =SUM(AG41:AG61) -> 2685.281 | AH39: =SUM(AH41:AH61) -> 31 | ... AZ39: =SUM(AZ41:AZ61) -> 90.151705
A40: Kategorie | B40: BLS Code | C40: Futtermittel | D40: Energie [kcal] | E40: Energie [MJ] | F40: Rohprotein [g] | G40: vRP | H40: Rohfett [g] | I40: NfE [g] | J40: Rohfaser [g] | K40: Rohasche [g] | L40: Wasser [g] | M40: TS [g] | N40: Calcium [mg] | O40: Phosphor [mg] | P40: Magnesium [mg] | Q40: Natrium [mg] | R40: Kalium [mg] | S40: Chlorid [mg] | T40: Eisen [mg] | U40: Zink [mg] | V40: Selen [µg] | W40: Kupfer [mg] | X40: Mangan [mg] | Y40: Jod [µg] | Z40: Schwefel [mg] | AA40: Vitamin D3 [µg] | AB40: Vitamin E [mg] | AC40: Vitamin A [µg] | AD40: Vitamin B1 [µg] | AE40: Vitamin B2 [µg] | AF40: Vit. B3/Niacin [µg] | AG40: Vitamin B6 [µg] | AH40: Vitamin B12 [µg] | AI40: Vitamin C [mg] | AJ40: Vitamin K [µg] | AK40: Folsäure [µg] | AL40: Biotin [µg] | AM40: Lactose [g] | AN40: Omega-3, gesamt [mg] | AO40: EPA [mg] | AP40: DHA [mg] | AQ40: Omega-6, gesamt [mg] | AR40: Linolsäure [mg] | AS40: Arginin [mg] | AT40: Cystein [mg] | AU40: Histidin [mg] | AV40: Lysin [mg] | AW40: Methionin [mg] | AX40: Vitamin D I.E. | AY40: Vitamin A IE | AZ40: Vitamin E IE
A41: =_xlfn.XLOOKUP($A14, Lebensmitteldaten!$C:$C, Lebensmitteldaten!$A:$A, "") -> Fleisch | B41: =_xlfn.XLOOKUP($A14, Lebensmitteldaten!$C:$C, Lebensmitteldaten!$B:$B, "") -> V112100 | C41: =A14 -> Pferd Fleisch, roh | D41: =IFERROR((_xlfn.XLOOKUP($C41, Lebensmitteldaten!$C:$C, Lebensmitteldaten!D:D) * $B14) / 100, 0) -> 432 | E41: =IFERROR((_xlfn.XLOOKUP($C41, Lebensmitteldaten!$C:$C, Lebensmitteldaten!E:E) * $B14) / 100, 0) -> 1.8075314 | F41: =IFERROR((_xlfn.XLOOKUP($C41, Lebensmitteldaten!$C:$C, Lebensmitteldaten!F:F) * $B14) / 100, 0) -> 82.4 | G41: =IFERROR((_xlfn.XLOOKUP($C41, Lebensmitteldaten!$C:$C, Lebensmitteldaten!G:G) * $B14) / 100, 0) -> 70.04 | H41: =IFERROR((_xlfn.XLOOKUP($C41, Lebensmitteldaten!$C:$C, Lebensmitteldaten!H:H) * $B14) / 100, 0) -> 10.68 | I41: =IFERROR((_xlfn.XLOOKUP($C41, Lebensmitteldaten!$C:$C, Lebensmitteldaten!I:I) * $B14) / 100, 0) -> 2.2 | J41: =IFERROR((_xlfn.XLOOKUP($C41, Lebensmitteldaten!$C:$C, Lebensmitteldaten!J:J) * $B14) / 100, 0) -> 0 | K41: =IFERROR((_xlfn.XLOOKUP($C41, Lebensmitteldaten!$C:$C, Lebensmitteldaten!K:K) * $B14) / 100, 0) -> 3.92 | L41: =IFERROR((_xlfn.XLOOKUP($C41, Lebensmitteldaten!$C:$C, Lebensmitteldaten!L:L) * $B14) / 100, 0) -> 300.8 | M41: =IFERROR((_xlfn.XLOOKUP($C41, Lebensmitteldaten!$C:$C, Lebensmitteldaten!M:M) * $B14) / 100, 0) -> 99.2 | N41: =IFERROR((_xlfn.XLOOKUP($C41, Lebensmitteldaten!$C:$C, Lebensmitteldaten!N:N) * $B14) / 100, 0) -> 36.6 | O41: =IFERROR((_xlfn.XLOOKUP($C41, Lebensmitteldaten!$C:$C, Lebensmitteldaten!O:O) * $B14) / 100, 0) -> 864 | P41: =IFERROR((_xlfn.XLOOKUP($C41, Lebensmitteldaten!$C:$C, Lebensmitteldaten!P:P) * $B14) / 100, 0) -> 108 | Q41: =IFERROR((_xlfn.XLOOKUP($C41, Lebensmitteldaten!$C:$C, Lebensmitteldaten!Q:Q) * $B14) / 100, 0) -> 176 | R41: =IFERROR((_xlfn.XLOOKUP($C41, Lebensmitteldaten!$C:$C, Lebensmitteldaten!R:R) * $B14) / 100, 0) -> 1600 | S41: =IFERROR((_xlfn.XLOOKUP($C41, Lebensmitteldaten!$C:$C, Lebensmitteldaten!S:S) * $B14) / 100, 0) -> 0 | T41: =IFERROR((_xlfn.XLOOKUP($C41, Lebensmitteldaten!$C:$C, Lebensmitteldaten!T:T) * $B14) / 100, 0) -> 19.6 | U41: =IFERROR((_xlfn.XLOOKUP($C41, Lebensmitteldaten!$C:$C, Lebensmitteldaten!U:U) * $B14) / 100, 0) -> 19.6 | V41: =IFERROR((_xlfn.XLOOKUP($C41, Lebensmitteldaten!$C:$C, Lebensmitteldaten!V:V) * $B14) / 100, 0) -> 0 | W41: =IFERROR((_xlfn.XLOOKUP($C41, Lebensmitteldaten!$C:$C, Lebensmitteldaten!W:W) * $B14) / 100 / 1000, 0) -> 0.84 | X41: =IFERROR((_xlfn.XLOOKUP($C41, Lebensmitteldaten!$C:$C, Lebensmitteldaten!X:X) * $B14) / 100 / 1000, 0) -> 0.096 | Y41: =IFERROR((_xlfn.XLOOKUP($C41, Lebensmitteldaten!$C:$C, Lebensmitteldaten!Y:Y) * $B14) / 100, 0) -> 23.2 | Z41: =IFERROR((_xlfn.XLOOKUP($C41, Lebensmitteldaten!$C:$C, Lebensmitteldaten!Z:Z) * $B14) / 100, 0) -> 0 | AA41: =IFERROR((_xlfn.XLOOKUP($C41, Lebensmitteldaten!$C:$C, Lebensmitteldaten!AA:AA) * $B14) / 100, 0) -> 1.6 | AB41: =IFERROR((_xlfn.XLOOKUP($C41, Lebensmitteldaten!$C:$C, Lebensmitteldaten!AB:AB) * $B14) / 100, 0) -> 1.88 | AC41: =IFERROR((_xlfn.XLOOKUP($C41, Lebensmitteldaten!$C:$C, Lebensmitteldaten!AC:AC) * $B14) / 100, 0) -> 84 | AD41: =IFERROR((_xlfn.XLOOKUP($C41, Lebensmitteldaten!$C:$C, Lebensmitteldaten!AD:AD) * $B14) / 100 * 1000, 0) -> 440 | AE41: =IFERROR((_xlfn.XLOOKUP($C41, Lebensmitteldaten!$C:$C, Lebensmitteldaten!AE:AE) * $B14) / 100 * 1000, 0) -> 600 | AF41: =IFERROR((_xlfn.XLOOKUP($C41, Lebensmitteldaten!$C:$C, Lebensmitteldaten!AF:AF) * $B14) / 100 * 1000, 0) -> 18400 | AG41: =IFERROR((_xlfn.XLOOKUP($C41, Lebensmitteldaten!$C:$C, Lebensmitteldaten!AG:AG) * $B14) / 100, 0) -> 2000 | AH41: =IFERROR((_xlfn.XLOOKUP($C41, Lebensmitteldaten!$C:$C, Lebensmitteldaten!AH:AH) * $B14) / 100, 0) -> 12 | AI41: =IFERROR((_xlfn.XLOOKUP($C41, Lebensmitteldaten!$C:$C, Lebensmitteldaten!AI:AI) * $B14) / 100, 0) -> 0 | AJ41: =IFERROR((_xlfn.XLOOKUP($C41, Lebensmitteldaten!$C:$C, Lebensmitteldaten!AJ:AJ) * $B14) / 100, 0) -> 6.8 | AK41: =IFERROR((_xlfn.XLOOKUP($C41, Lebensmitteldaten!$C:$C, Lebensmitteldaten!AK:AK) * $B14) / 100, 0) -> 12 | AL41: =IFERROR((_xlfn.XLOOKUP($C41, Lebensmitteldaten!$C:$C, Lebensmitteldaten!AL:AL) * $B14) / 100, 0) -> 12 | AM41: =IFERROR((_xlfn.XLOOKUP($C41, Lebensmitteldaten!$C:$C, Lebensmitteldaten!AM:AM) * $B14) / 100, 0) -> 0 | AN41: =IFERROR((_xlfn.XLOOKUP($C41, Lebensmitteldaten!$C:$C, Lebensmitteldaten!AN:AN) * $B14) / 100 * 1000, 0) -> 1069.332 | AO41: =IFERROR((_xlfn.XLOOKUP($C41, Lebensmitteldaten!$C:$C, Lebensmitteldaten!AO:AO) * $B14) / 100 * 1000, 0) -> 0 | AP41: =IFERROR((_xlfn.XLOOKUP($C41, Lebensmitteldaten!$C:$C, Lebensmitteldaten!AP:AP) * $B14) / 100 * 1000, 0) -> 0 | AQ41: =IFERROR((_xlfn.XLOOKUP($C41, Lebensmitteldaten!$C:$C, Lebensmitteldaten!AQ:AQ) * $B14) / 100 * 1000, 0) -> 1196 | AR41: =IFERROR((_xlfn.XLOOKUP($C41, Lebensmitteldaten!$C:$C, Lebensmitteldaten!AR:AR) * $B14) / 100 * 1000, 0) -> 714.668 | AS41: =IFERROR((_xlfn.XLOOKUP($C41, Lebensmitteldaten!$C:$C, Lebensmitteldaten!AS:AS) * $B14) / 100 * 1000, 0) -> 7160 | AT41: =IFERROR((_xlfn.XLOOKUP($C41, Lebensmitteldaten!$C:$C, Lebensmitteldaten!AT:AT) * $B14) / 100 * 1000, 0) -> 0 | AU41: =IFERROR((_xlfn.XLOOKUP($C41, Lebensmitteldaten!$C:$C, Lebensmitteldaten!AU:AU) * $B14) / 100 * 1000, 0) -> 3480 | AV41: =IFERROR((_xlfn.XLOOKUP($C41, Lebensmitteldaten!$C:$C, Lebensmitteldaten!AV:AV) * $B14) / 100 * 1000, 0) -> 6280 | AW41: =IFERROR((_xlfn.XLOOKUP($C41, Lebensmitteldaten!$C:$C, Lebensmitteldaten!AW:AW) * $B14) / 100 * 1000, 0) -> 5120 | AX41: =IFERROR((_xlfn.XLOOKUP($C41, Lebensmitteldaten!$C:$C, Lebensmitteldaten!AX:AX) * $B14) / 100, 0) -> 64 | AY41: =IFERROR((_xlfn.XLOOKUP($C41, Lebensmitteldaten!$C:$C, Lebensmitteldaten!AY:AY) * $B14) / 100, 0) -> 279.72 | AZ41: =IFERROR((_xlfn.XLOOKUP($C41, Lebensmitteldaten!$C:$C, Lebensmitteldaten!AZ:AZ) * $B14) / 100, 0) -> 2.8012
A42: =_xlfn.XLOOKUP($A15, Lebensmitteldaten!$C:$C, Lebensmitteldaten!$A:$A, "") -> Gemüse | B42: =_xlfn.XLOOKUP($A15, Lebensmitteldaten!$C:$C, Lebensmitteldaten!$B:$B, "") -> G582152 | C42: =A15 -> Zucchini gedünstet | D42: =IFERROR((_xlfn.XLOOKUP($C42, Lebensmitteldaten!$C:$C, Lebensmitteldaten!D:D) * $B15) / 100, 0) -> 6.9 | E42: =IFERROR((_xlfn.XLOOKUP($C42, Lebensmitteldaten!$C:$C, Lebensmitteldaten!E:E) * $B15) / 100, 0) -> 0.028870293 | F42: =IFERROR((_xlfn.XLOOKUP($C42, Lebensmitteldaten!$C:$C, Lebensmitteldaten!F:F) * $B15) / 100, 0) -> 0.42 | G42: =IFERROR((_xlfn.XLOOKUP($C42, Lebensmitteldaten!$C:$C, Lebensmitteldaten!G:G) * $B15) / 100, 0) -> 0.357 | H42: =IFERROR((_xlfn.XLOOKUP($C42, Lebensmitteldaten!$C:$C, Lebensmitteldaten!H:H) * $B15) / 100, 0) -> 0.0936 | I42: =IFERROR((_xlfn.XLOOKUP($C42, Lebensmitteldaten!$C:$C, Lebensmitteldaten!I:I) * $B15) / 100, 0) -> 0.6864 | J42: =IFERROR((_xlfn.XLOOKUP($C42, Lebensmitteldaten!$C:$C, Lebensmitteldaten!J:J) * $B15) / 100, 0) -> 0 | K42: =IFERROR((_xlfn.XLOOKUP($C42, Lebensmitteldaten!$C:$C, Lebensmitteldaten!K:K) * $B15) / 100, 0) -> 0.3 | L42: =IFERROR((_xlfn.XLOOKUP($C42, Lebensmitteldaten!$C:$C, Lebensmitteldaten!L:L) * $B15) / 100, 0) -> 28.5 | M42: =IFERROR((_xlfn.XLOOKUP($C42, Lebensmitteldaten!$C:$C, Lebensmitteldaten!M:M) * $B15) / 100, 0) -> 1.5 | N42: =IFERROR((_xlfn.XLOOKUP($C42, Lebensmitteldaten!$C:$C, Lebensmitteldaten!N:N) * $B15) / 100, 0) -> 6.651 | O42: =IFERROR((_xlfn.XLOOKUP($C42, Lebensmitteldaten!$C:$C, Lebensmitteldaten!O:O) * $B15) / 100, 0) -> 14.67 | P42: =IFERROR((_xlfn.XLOOKUP($C42, Lebensmitteldaten!$C:$C, Lebensmitteldaten!P:P) * $B15) / 100, 0) -> 9.33 | Q42: =IFERROR((_xlfn.XLOOKUP($C42, Lebensmitteldaten!$C:$C, Lebensmitteldaten!Q:Q) * $B15) / 100, 0) -> 0.351 | R42: =IFERROR((_xlfn.XLOOKUP($C42, Lebensmitteldaten!$C:$C, Lebensmitteldaten!R:R) * $B15) / 100, 0) -> 84.012 | S42: =IFERROR((_xlfn.XLOOKUP($C42, Lebensmitteldaten!$C:$C, Lebensmitteldaten!S:S) * $B15) / 100, 0) -> 0 | T42: =IFERROR((_xlfn.XLOOKUP($C42, Lebensmitteldaten!$C:$C, Lebensmitteldaten!T:T) * $B15) / 100, 0) -> 0.12 | U42: =IFERROR((_xlfn.XLOOKUP($C42, Lebensmitteldaten!$C:$C, Lebensmitteldaten!U:U) * $B15) / 100, 0) -> 0.078 | V42: =IFERROR((_xlfn.XLOOKUP($C42, Lebensmitteldaten!$C:$C, Lebensmitteldaten!V:V) * $B15) / 100, 0) -> 0 | W42: =IFERROR((_xlfn.XLOOKUP($C42, Lebensmitteldaten!$C:$C, Lebensmitteldaten!W:W) * $B15) / 100 / 1000, 0) -> 0.021 | X42: =IFERROR((_xlfn.XLOOKUP($C42, Lebensmitteldaten!$C:$C, Lebensmitteldaten!X:X) * $B15) / 100 / 1000, 0) -> 0.03 | Y42: =IFERROR((_xlfn.XLOOKUP($C42, Lebensmitteldaten!$C:$C, Lebensmitteldaten!Y:Y) * $B15) / 100, 0) -> 0.792 | Z42: =IFERROR((_xlfn.XLOOKUP($C42, Lebensmitteldaten!$C:$C, Lebensmitteldaten!Z:Z) * $B15) / 100, 0) -> 0 | AA42: =IFERROR((_xlfn.XLOOKUP($C42, Lebensmitteldaten!$C:$C, Lebensmitteldaten!AA:AA) * $B15) / 100, 0) -> 0 | AB42: =IFERROR((_xlfn.XLOOKUP($C42, Lebensmitteldaten!$C:$C, Lebensmitteldaten!AB:AB) * $B15) / 100, 0) -> 0.102 | AC42: =IFERROR((_xlfn.XLOOKUP($C42, Lebensmitteldaten!$C:$C, Lebensmitteldaten!AC:AC) * $B15) / 100, 0) -> 10.2 | AD42: =IFERROR((_xlfn.XLOOKUP($C42, Lebensmitteldaten!$C:$C, Lebensmitteldaten!AD:AD) * $B15) / 100 * 1000, 0) -> 9 | AE42: =IFERROR((_xlfn.XLOOKUP($C42, Lebensmitteldaten!$C:$C, Lebensmitteldaten!AE:AE) * $B15) / 100 * 1000, 0) -> 6 | AF42: =IFERROR((_xlfn.XLOOKUP($C42, Lebensmitteldaten!$C:$C, Lebensmitteldaten!AF:AF) * $B15) / 100 * 1000, 0) -> 126.3 | AG42: =IFERROR((_xlfn.XLOOKUP($C42, Lebensmitteldaten!$C:$C, Lebensmitteldaten!AG:AG) * $B15) / 100, 0) -> 18 | AH42: =IFERROR((_xlfn.XLOOKUP($C42, Lebensmitteldaten!$C:$C, Lebensmitteldaten!AH:AH) * $B15) / 100, 0) -> 0 | AI42: =IFERROR((_xlfn.XLOOKUP($C42, Lebensmitteldaten!$C:$C, Lebensmitteldaten!AI:AI) * $B15) / 100, 0) -> 4.5912 | AJ42: =IFERROR((_xlfn.XLOOKUP($C42, Lebensmitteldaten!$C:$C, Lebensmitteldaten!AJ:AJ) * $B15) / 100, 0) -> 10.5 | AK42: =IFERROR((_xlfn.XLOOKUP($C42, Lebensmitteldaten!$C:$C, Lebensmitteldaten!AK:AK) * $B15) / 100, 0) -> 9.6 | AL42: =IFERROR((_xlfn.XLOOKUP($C42, Lebensmitteldaten!$C:$C, Lebensmitteldaten!AL:AL) * $B15) / 100, 0) -> 1.02 | AM42: =IFERROR((_xlfn.XLOOKUP($C42, Lebensmitteldaten!$C:$C, Lebensmitteldaten!AM:AM) * $B15) / 100, 0) -> 0 | AN42: =IFERROR((_xlfn.XLOOKUP($C42, Lebensmitteldaten!$C:$C, Lebensmitteldaten!AN:AN) * $B15) / 100 * 1000, 0) -> 28.5 | AO42: =IFERROR((_xlfn.XLOOKUP($C42, Lebensmitteldaten!$C:$C, Lebensmitteldaten!AO:AO) * $B15) / 100 * 1000, 0) -> 0 | AP42: =IFERROR((_xlfn.XLOOKUP($C42, Lebensmitteldaten!$C:$C, Lebensmitteldaten!AP:AP) * $B15) / 100 * 1000, 0) -> 0 | AQ42: =IFERROR((_xlfn.XLOOKUP($C42, Lebensmitteldaten!$C:$C, Lebensmitteldaten!AQ:AQ) * $B15) / 100 * 1000, 0) -> 17.1 | AR42: =IFERROR((_xlfn.XLOOKUP($C42, Lebensmitteldaten!$C:$C, Lebensmitteldaten!AR:AR) * $B15) / 100 * 1000, 0) -> 17.1 | AS42: =IFERROR((_xlfn.XLOOKUP($C42, Lebensmitteldaten!$C:$C, Lebensmitteldaten!AS:AS) * $B15) / 100 * 1000, 0) -> 0 | AT42: =IFERROR((_xlfn.XLOOKUP($C42, Lebensmitteldaten!$C:$C, Lebensmitteldaten!AT:AT) * $B15) / 100 * 1000, 0) -> 0 | AU42: =IFERROR((_xlfn.XLOOKUP($C42, Lebensmitteldaten!$C:$C, Lebensmitteldaten!AU:AU) * $B15) / 100 * 1000, 0) -> 0 | AV42: =IFERROR((_xlfn.XLOOKUP($C42, Lebensmitteldaten!$C:$C, Lebensmitteldaten!AV:AV) * $B15) / 100 * 1000, 0) -> 0 | AW42: =IFERROR((_xlfn.XLOOKUP($C42, Lebensmitteldaten!$C:$C, Lebensmitteldaten!AW:AW) * $B15) / 100 * 1000, 0) -> 0 | AX42: =IFERROR((_xlfn.XLOOKUP($C42, Lebensmitteldaten!$C:$C, Lebensmitteldaten!AX:AX) * $B15) / 100, 0) -> 0 | AY42: =IFERROR((_xlfn.XLOOKUP($C42, Lebensmitteldaten!$C:$C, Lebensmitteldaten!AY:AY) * $B15) / 100, 0) -> 33.966 | AZ42: =IFERROR((_xlfn.XLOOKUP($C42, Lebensmitteldaten!$C:$C, Lebensmitteldaten!AZ:AZ) * $B15) / 100, 0) -> 0.15198
A43: =_xlfn.XLOOKUP($A16, Lebensmitteldaten!$C:$C, Lebensmitteldaten!$A:$A, "") -> Gemüse | B43: =_xlfn.XLOOKUP($A16, Lebensmitteldaten!$C:$C, Lebensmitteldaten!$B:$B, "") -> G620132 | C43: =A16 -> Karotte/Möhre, gekocht | D43: =IFERROR((_xlfn.XLOOKUP($C43, Lebensmitteldaten!$C:$C, Lebensmitteldaten!D:D) * $B16) / 100, 0) -> 30.6 | E43: =IFERROR((_xlfn.XLOOKUP($C43, Lebensmitteldaten!$C:$C, Lebensmitteldaten!E:E) * $B16) / 100, 0) -> 0.12803347 | F43: =IFERROR((_xlfn.XLOOKUP($C43, Lebensmitteldaten!$C:$C, Lebensmitteldaten!F:F) * $B16) / 100, 0) -> 0.45 | G43: =IFERROR((_xlfn.XLOOKUP($C43, Lebensmitteldaten!$C:$C, Lebensmitteldaten!G:G) * $B16) / 100, 0) -> 0.3825 | H43: =IFERROR((_xlfn.XLOOKUP($C43, Lebensmitteldaten!$C:$C, Lebensmitteldaten!H:H) * $B16) / 100, 0) -> 0.45 | I43: =IFERROR((_xlfn.XLOOKUP($C43, Lebensmitteldaten!$C:$C, Lebensmitteldaten!I:I) * $B16) / 100, 0) -> 8.37 | J43: =IFERROR((_xlfn.XLOOKUP($C43, Lebensmitteldaten!$C:$C, Lebensmitteldaten!J:J) * $B16) / 100, 0) -> 0 | K43: =IFERROR((_xlfn.XLOOKUP($C43, Lebensmitteldaten!$C:$C, Lebensmitteldaten!K:K) * $B16) / 100, 0) -> 0.45 | L43: =IFERROR((_xlfn.XLOOKUP($C43, Lebensmitteldaten!$C:$C, Lebensmitteldaten!L:L) * $B16) / 100, 0) -> 80.28 | M43: =IFERROR((_xlfn.XLOOKUP($C43, Lebensmitteldaten!$C:$C, Lebensmitteldaten!M:M) * $B16) / 100, 0) -> 9.72 | N43: =IFERROR((_xlfn.XLOOKUP($C43, Lebensmitteldaten!$C:$C, Lebensmitteldaten!N:N) * $B16) / 100, 0) -> 27.9 | O43: =IFERROR((_xlfn.XLOOKUP($C43, Lebensmitteldaten!$C:$C, Lebensmitteldaten!O:O) * $B16) / 100, 0) -> 25.38 | P43: =IFERROR((_xlfn.XLOOKUP($C43, Lebensmitteldaten!$C:$C, Lebensmitteldaten!P:P) * $B16) / 100, 0) -> 7.2 | Q43: =IFERROR((_xlfn.XLOOKUP($C43, Lebensmitteldaten!$C:$C, Lebensmitteldaten!Q:Q) * $B16) / 100, 0) -> 26.1 | R43: =IFERROR((_xlfn.XLOOKUP($C43, Lebensmitteldaten!$C:$C, Lebensmitteldaten!R:R) * $B16) / 100, 0) -> 149.4 | S43: =IFERROR((_xlfn.XLOOKUP($C43, Lebensmitteldaten!$C:$C, Lebensmitteldaten!S:S) * $B16) / 100, 0) -> 0 | T43: =IFERROR((_xlfn.XLOOKUP($C43, Lebensmitteldaten!$C:$C, Lebensmitteldaten!T:T) * $B16) / 100, 0) -> 0.306 | U43: =IFERROR((_xlfn.XLOOKUP($C43, Lebensmitteldaten!$C:$C, Lebensmitteldaten!U:U) * $B16) / 100, 0) -> 0.117 | V43: =IFERROR((_xlfn.XLOOKUP($C43, Lebensmitteldaten!$C:$C, Lebensmitteldaten!V:V) * $B16) / 100, 0) -> 0 | W43: =IFERROR((_xlfn.XLOOKUP($C43, Lebensmitteldaten!$C:$C, Lebensmitteldaten!W:W) * $B16) / 100 / 1000, 0) -> 0.0153 | X43: =IFERROR((_xlfn.XLOOKUP($C43, Lebensmitteldaten!$C:$C, Lebensmitteldaten!X:X) * $B16) / 100 / 1000, 0) -> 0.1062 | Y43: =IFERROR((_xlfn.XLOOKUP($C43, Lebensmitteldaten!$C:$C, Lebensmitteldaten!Y:Y) * $B16) / 100, 0) -> 2.61 | Z43: =IFERROR((_xlfn.XLOOKUP($C43, Lebensmitteldaten!$C:$C, Lebensmitteldaten!Z:Z) * $B16) / 100, 0) -> 0 | AA43: =IFERROR((_xlfn.XLOOKUP($C43, Lebensmitteldaten!$C:$C, Lebensmitteldaten!AA:AA) * $B16) / 100, 0) -> 0 | AB43: =IFERROR((_xlfn.XLOOKUP($C43, Lebensmitteldaten!$C:$C, Lebensmitteldaten!AB:AB) * $B16) / 100, 0) -> 0.72 | AC43: =IFERROR((_xlfn.XLOOKUP($C43, Lebensmitteldaten!$C:$C, Lebensmitteldaten!AC:AC) * $B16) / 100, 0) -> 162 | AD43: =IFERROR((_xlfn.XLOOKUP($C43, Lebensmitteldaten!$C:$C, Lebensmitteldaten!AD:AD) * $B16) / 100 * 1000, 0) -> 81 | AE43: =IFERROR((_xlfn.XLOOKUP($C43, Lebensmitteldaten!$C:$C, Lebensmitteldaten!AE:AE) * $B16) / 100 * 1000, 0) -> 18 | AF43: =IFERROR((_xlfn.XLOOKUP($C43, Lebensmitteldaten!$C:$C, Lebensmitteldaten!AF:AF) * $B16) / 100 * 1000, 0) -> 180 | AG43: =IFERROR((_xlfn.XLOOKUP($C43, Lebensmitteldaten!$C:$C, Lebensmitteldaten!AG:AG) * $B16) / 100, 0) -> 24.381 | AH43: =IFERROR((_xlfn.XLOOKUP($C43, Lebensmitteldaten!$C:$C, Lebensmitteldaten!AH:AH) * $B16) / 100, 0) -> 0 | AI43: =IFERROR((_xlfn.XLOOKUP($C43, Lebensmitteldaten!$C:$C, Lebensmitteldaten!AI:AI) * $B16) / 100, 0) -> 4.5 | AJ43: =IFERROR((_xlfn.XLOOKUP($C43, Lebensmitteldaten!$C:$C, Lebensmitteldaten!AJ:AJ) * $B16) / 100, 0) -> 9.9 | AK43: =IFERROR((_xlfn.XLOOKUP($C43, Lebensmitteldaten!$C:$C, Lebensmitteldaten!AK:AK) * $B16) / 100, 0) -> 27.9 | AL43: =IFERROR((_xlfn.XLOOKUP($C43, Lebensmitteldaten!$C:$C, Lebensmitteldaten!AL:AL) * $B16) / 100, 0) -> 0.27 | AM43: =IFERROR((_xlfn.XLOOKUP($C43, Lebensmitteldaten!$C:$C, Lebensmitteldaten!AM:AM) * $B16) / 100, 0) -> 0 | AN43: =IFERROR((_xlfn.XLOOKUP($C43, Lebensmitteldaten!$C:$C, Lebensmitteldaten!AN:AN) * $B16) / 100 * 1000, 0) -> 4.86 | AO43: =IFERROR((_xlfn.XLOOKUP($C43, Lebensmitteldaten!$C:$C, Lebensmitteldaten!AO:AO) * $B16) / 100 * 1000, 0) -> 0 | AP43: =IFERROR((_xlfn.XLOOKUP($C43, Lebensmitteldaten!$C:$C, Lebensmitteldaten!AP:AP) * $B16) / 100 * 1000, 0) -> 0 | AQ43: =IFERROR((_xlfn.XLOOKUP($C43, Lebensmitteldaten!$C:$C, Lebensmitteldaten!AQ:AQ) * $B16) / 100 * 1000, 0) -> 62.37 | AR43: =IFERROR((_xlfn.XLOOKUP($C43, Lebensmitteldaten!$C:$C, Lebensmitteldaten!AR:AR) * $B16) / 100 * 1000, 0) -> 61.02 | AS43: =IFERROR((_xlfn.XLOOKUP($C43, Lebensmitteldaten!$C:$C, Lebensmitteldaten!AS:AS) * $B16) / 100 * 1000, 0) -> 36.9 | AT43: =IFERROR((_xlfn.XLOOKUP($C43, Lebensmitteldaten!$C:$C, Lebensmitteldaten!AT:AT) * $B16) / 100 * 1000, 0) -> 11.7 | AU43: =IFERROR((_xlfn.XLOOKUP($C43, Lebensmitteldaten!$C:$C, Lebensmitteldaten!AU:AU) * $B16) / 100 * 1000, 0) -> 13.5 | AV43: =IFERROR((_xlfn.XLOOKUP($C43, Lebensmitteldaten!$C:$C, Lebensmitteldaten!AV:AV) * $B16) / 100 * 1000, 0) -> 42.3 | AW43: =IFERROR((_xlfn.XLOOKUP($C43, Lebensmitteldaten!$C:$C, Lebensmitteldaten!AW:AW) * $B16) / 100 * 1000, 0) -> 7.2 | AX43: =IFERROR((_xlfn.XLOOKUP($C43, Lebensmitteldaten!$C:$C, Lebensmitteldaten!AX:AX) * $B16) / 100, 0) -> 0 | AY43: =IFERROR((_xlfn.XLOOKUP($C43, Lebensmitteldaten!$C:$C, Lebensmitteldaten!AY:AY) * $B16) / 100, 0) -> 539.46 | AZ43: =IFERROR((_xlfn.XLOOKUP($C43, Lebensmitteldaten!$C:$C, Lebensmitteldaten!AZ:AZ) * $B16) / 100, 0) -> 1.0728
A44: =_xlfn.XLOOKUP($A17, Lebensmitteldaten!$C:$C, Lebensmitteldaten!$A:$A, "") -> Kohlenhydrate | B44: =_xlfn.XLOOKUP($A17, Lebensmitteldaten!$C:$C, Lebensmitteldaten!$B:$B, "") -> C352000 | C44: =A17 -> Reis poliert, roh | D44: =IFERROR((_xlfn.XLOOKUP($C44, Lebensmitteldaten!$C:$C, Lebensmitteldaten!D:D) * $B17) / 100, 0) -> 140.4 | E44: =IFERROR((_xlfn.XLOOKUP($C44, Lebensmitteldaten!$C:$C, Lebensmitteldaten!E:E) * $B17) / 100, 0) -> 0.5874477 | F44: =IFERROR((_xlfn.XLOOKUP($C44, Lebensmitteldaten!$C:$C, Lebensmitteldaten!F:F) * $B17) / 100, 0) -> 3.1724 | G44: =IFERROR((_xlfn.XLOOKUP($C44, Lebensmitteldaten!$C:$C, Lebensmitteldaten!G:G) * $B17) / 100, 0) -> 2.69654 | H44: =IFERROR((_xlfn.XLOOKUP($C44, Lebensmitteldaten!$C:$C, Lebensmitteldaten!H:H) * $B17) / 100, 0) -> 0.248 | I44: =IFERROR((_xlfn.XLOOKUP($C44, Lebensmitteldaten!$C:$C, Lebensmitteldaten!I:I) * $B17) / 100, 0) -> 31.6516 | J44: =IFERROR((_xlfn.XLOOKUP($C44, Lebensmitteldaten!$C:$C, Lebensmitteldaten!J:J) * $B17) / 100, 0) -> 0 | K44: =IFERROR((_xlfn.XLOOKUP($C44, Lebensmitteldaten!$C:$C, Lebensmitteldaten!K:K) * $B17) / 100, 0) -> 0.176 | L44: =IFERROR((_xlfn.XLOOKUP($C44, Lebensmitteldaten!$C:$C, Lebensmitteldaten!L:L) * $B17) / 100, 0) -> 4.752 | M44: =IFERROR((_xlfn.XLOOKUP($C44, Lebensmitteldaten!$C:$C, Lebensmitteldaten!M:M) * $B17) / 100, 0) -> 35.248 | N44: =IFERROR((_xlfn.XLOOKUP($C44, Lebensmitteldaten!$C:$C, Lebensmitteldaten!N:N) * $B17) / 100, 0) -> 2 | O44: =IFERROR((_xlfn.XLOOKUP($C44, Lebensmitteldaten!$C:$C, Lebensmitteldaten!O:O) * $B17) / 100, 0) -> 45.408 | P44: =IFERROR((_xlfn.XLOOKUP($C44, Lebensmitteldaten!$C:$C, Lebensmitteldaten!P:P) * $B17) / 100, 0) -> 16.192 | Q44: =IFERROR((_xlfn.XLOOKUP($C44, Lebensmitteldaten!$C:$C, Lebensmitteldaten!Q:Q) * $B17) / 100, 0) -> 6.308 | R44: =IFERROR((_xlfn.XLOOKUP($C44, Lebensmitteldaten!$C:$C, Lebensmitteldaten!R:R) * $B17) / 100, 0) -> 42.648 | S44: =IFERROR((_xlfn.XLOOKUP($C44, Lebensmitteldaten!$C:$C, Lebensmitteldaten!S:S) * $B17) / 100, 0) -> 0 | T44: =IFERROR((_xlfn.XLOOKUP($C44, Lebensmitteldaten!$C:$C, Lebensmitteldaten!T:T) * $B17) / 100, 0) -> 0.116596 | U44: =IFERROR((_xlfn.XLOOKUP($C44, Lebensmitteldaten!$C:$C, Lebensmitteldaten!U:U) * $B17) / 100, 0) -> 1.213244 | V44: =IFERROR((_xlfn.XLOOKUP($C44, Lebensmitteldaten!$C:$C, Lebensmitteldaten!V:V) * $B17) / 100, 0) -> 0 | W44: =IFERROR((_xlfn.XLOOKUP($C44, Lebensmitteldaten!$C:$C, Lebensmitteldaten!W:W) * $B17) / 100 / 1000, 0) -> 0.100492 | X44: =IFERROR((_xlfn.XLOOKUP($C44, Lebensmitteldaten!$C:$C, Lebensmitteldaten!X:X) * $B17) / 100 / 1000, 0) -> 0.280772 | Y44: =IFERROR((_xlfn.XLOOKUP($C44, Lebensmitteldaten!$C:$C, Lebensmitteldaten!Y:Y) * $B17) / 100, 0) -> 2.476 | Z44: =IFERROR((_xlfn.XLOOKUP($C44, Lebensmitteldaten!$C:$C, Lebensmitteldaten!Z:Z) * $B17) / 100, 0) -> 0 | AA44: =IFERROR((_xlfn.XLOOKUP($C44, Lebensmitteldaten!$C:$C, Lebensmitteldaten!AA:AA) * $B17) / 100, 0) -> 0 | AB44: =IFERROR((_xlfn.XLOOKUP($C44, Lebensmitteldaten!$C:$C, Lebensmitteldaten!AB:AB) * $B17) / 100, 0) -> 0.0212 | AC44: =IFERROR((_xlfn.XLOOKUP($C44, Lebensmitteldaten!$C:$C, Lebensmitteldaten!AC:AC) * $B17) / 100, 0) -> 0 | AD44: =IFERROR((_xlfn.XLOOKUP($C44, Lebensmitteldaten!$C:$C, Lebensmitteldaten!AD:AD) * $B17) / 100 * 1000, 0) -> 50.4 | AE44: =IFERROR((_xlfn.XLOOKUP($C44, Lebensmitteldaten!$C:$C, Lebensmitteldaten!AE:AE) * $B17) / 100 * 1000, 0) -> 2 | AF44: =IFERROR((_xlfn.XLOOKUP($C44, Lebensmitteldaten!$C:$C, Lebensmitteldaten!AF:AF) * $B17) / 100 * 1000, 0) -> 520 | AG44: =IFERROR((_xlfn.XLOOKUP($C44, Lebensmitteldaten!$C:$C, Lebensmitteldaten!AG:AG) * $B17) / 100, 0) -> 19.2 | AH44: =IFERROR((_xlfn.XLOOKUP($C44, Lebensmitteldaten!$C:$C, Lebensmitteldaten!AH:AH) * $B17) / 100, 0) -> 0 | AI44: =IFERROR((_xlfn.XLOOKUP($C44, Lebensmitteldaten!$C:$C, Lebensmitteldaten!AI:AI) * $B17) / 100, 0) -> 0 | AJ44: =IFERROR((_xlfn.XLOOKUP($C44, Lebensmitteldaten!$C:$C, Lebensmitteldaten!AJ:AJ) * $B17) / 100, 0) -> 0.04 | AK44: =IFERROR((_xlfn.XLOOKUP($C44, Lebensmitteldaten!$C:$C, Lebensmitteldaten!AK:AK) * $B17) / 100, 0) -> 4.52 | AL44: =IFERROR((_xlfn.XLOOKUP($C44, Lebensmitteldaten!$C:$C, Lebensmitteldaten!AL:AL) * $B17) / 100, 0) -> 1.2 | AM44: =IFERROR((_xlfn.XLOOKUP($C44, Lebensmitteldaten!$C:$C, Lebensmitteldaten!AM:AM) * $B17) / 100, 0) -> 0 | AN44: =IFERROR((_xlfn.XLOOKUP($C44, Lebensmitteldaten!$C:$C, Lebensmitteldaten!AN:AN) * $B17) / 100 * 1000, 0) -> 4.8 | AO44: =IFERROR((_xlfn.XLOOKUP($C44, Lebensmitteldaten!$C:$C, Lebensmitteldaten!AO:AO) * $B17) / 100 * 1000, 0) -> 0 | AP44: =IFERROR((_xlfn.XLOOKUP($C44, Lebensmitteldaten!$C:$C, Lebensmitteldaten!AP:AP) * $B17) / 100 * 1000, 0) -> 0 | AQ44: =IFERROR((_xlfn.XLOOKUP($C44, Lebensmitteldaten!$C:$C, Lebensmitteldaten!AQ:AQ) * $B17) / 100 * 1000, 0) -> 88 | AR44: =IFERROR((_xlfn.XLOOKUP($C44, Lebensmitteldaten!$C:$C, Lebensmitteldaten!AR:AR) * $B17) / 100 * 1000, 0) -> 88 | AS44: =IFERROR((_xlfn.XLOOKUP($C44, Lebensmitteldaten!$C:$C, Lebensmitteldaten!AS:AS) * $B17) / 100 * 1000, 0) -> 228 | AT44: =IFERROR((_xlfn.XLOOKUP($C44, Lebensmitteldaten!$C:$C, Lebensmitteldaten!AT:AT) * $B17) / 100 * 1000, 0) -> 44 | AU44: =IFERROR((_xlfn.XLOOKUP($C44, Lebensmitteldaten!$C:$C, Lebensmitteldaten!AU:AU) * $B17) / 100 * 1000, 0) -> 68 | AV44: =IFERROR((_xlfn.XLOOKUP($C44, Lebensmitteldaten!$C:$C, Lebensmitteldaten!AV:AV) * $B17) / 100 * 1000, 0) -> 116 | AW44: =IFERROR((_xlfn.XLOOKUP($C44, Lebensmitteldaten!$C:$C, Lebensmitteldaten!AW:AW) * $B17) / 100 * 1000, 0) -> 68 | AX44: =IFERROR((_xlfn.XLOOKUP($C44, Lebensmitteldaten!$C:$C, Lebensmitteldaten!AX:AX) * $B17) / 100, 0) -> 0 | AY44: =IFERROR((_xlfn.XLOOKUP($C44, Lebensmitteldaten!$C:$C, Lebensmitteldaten!AY:AY) * $B17) / 100, 0) -> 0 | AZ44: =IFERROR((_xlfn.XLOOKUP($C44, Lebensmitteldaten!$C:$C, Lebensmitteldaten!AZ:AZ) * $B17) / 100, 0) -> 0.031588
A45: =_xlfn.XLOOKUP($A18, Lebensmitteldaten!$C:$C, Lebensmitteldaten!$A:$A, "") -> Fette | B45: =_xlfn.XLOOKUP($A18, Lebensmitteldaten!$C:$C, Lebensmitteldaten!$B:$B, "") -> 0 | C45: =A18 -> Anchovisöl Kochen für Hunde | D45: =IFERROR((_xlfn.XLOOKUP($C45, Lebensmitteldaten!$C:$C, Lebensmitteldaten!D:D) * $B18) / 100, 0) -> 50.49 | E45: =IFERROR((_xlfn.XLOOKUP($C45, Lebensmitteldaten!$C:$C, Lebensmitteldaten!E:E) * $B18) / 100, 0) -> 0.21125523 | F45: =IFERROR((_xlfn.XLOOKUP($C45, Lebensmitteldaten!$C:$C, Lebensmitteldaten!F:F) * $B18) / 100, 0) -> 0 | G45: =IFERROR((_xlfn.XLOOKUP($C45, Lebensmitteldaten!$C:$C, Lebensmitteldaten!G:G) * $B18) / 100, 0) -> 0 | H45: =IFERROR((_xlfn.XLOOKUP($C45, Lebensmitteldaten!$C:$C, Lebensmitteldaten!H:H) * $B18) / 100, 0) -> 5.94 | I45: =IFERROR((_xlfn.XLOOKUP($C45, Lebensmitteldaten!$C:$C, Lebensmitteldaten!I:I) * $B18) / 100, 0) -> 0.06 | J45: =IFERROR((_xlfn.XLOOKUP($C45, Lebensmitteldaten!$C:$C, Lebensmitteldaten!J:J) * $B18) / 100, 0) -> 0 | K45: =IFERROR((_xlfn.XLOOKUP($C45, Lebensmitteldaten!$C:$C, Lebensmitteldaten!K:K) * $B18) / 100, 0) -> 0 | L45: =IFERROR((_xlfn.XLOOKUP($C45, Lebensmitteldaten!$C:$C, Lebensmitteldaten!L:L) * $B18) / 100, 0) -> 0 | M45: =IFERROR((_xlfn.XLOOKUP($C45, Lebensmitteldaten!$C:$C, Lebensmitteldaten!M:M) * $B18) / 100, 0) -> 6 | N45: =IFERROR((_xlfn.XLOOKUP($C45, Lebensmitteldaten!$C:$C, Lebensmitteldaten!N:N) * $B18) / 100, 0) -> 0 | O45: =IFERROR((_xlfn.XLOOKUP($C45, Lebensmitteldaten!$C:$C, Lebensmitteldaten!O:O) * $B18) / 100, 0) -> 0 | P45: =IFERROR((_xlfn.XLOOKUP($C45, Lebensmitteldaten!$C:$C, Lebensmitteldaten!P:P) * $B18) / 100, 0) -> 0 | Q45: =IFERROR((_xlfn.XLOOKUP($C45, Lebensmitteldaten!$C:$C, Lebensmitteldaten!Q:Q) * $B18) / 100, 0) -> 0 | R45: =IFERROR((_xlfn.XLOOKUP($C45, Lebensmitteldaten!$C:$C, Lebensmitteldaten!R:R) * $B18) / 100, 0) -> 0 | S45: =IFERROR((_xlfn.XLOOKUP($C45, Lebensmitteldaten!$C:$C, Lebensmitteldaten!S:S) * $B18) / 100, 0) -> 0 | T45: =IFERROR((_xlfn.XLOOKUP($C45, Lebensmitteldaten!$C:$C, Lebensmitteldaten!T:T) * $B18) / 100, 0) -> 0 | U45: =IFERROR((_xlfn.XLOOKUP($C45, Lebensmitteldaten!$C:$C, Lebensmitteldaten!U:U) * $B18) / 100, 0) -> 0 | V45: =IFERROR((_xlfn.XLOOKUP($C45, Lebensmitteldaten!$C:$C, Lebensmitteldaten!V:V) * $B18) / 100, 0) -> 0 | W45: =IFERROR((_xlfn.XLOOKUP($C45, Lebensmitteldaten!$C:$C, Lebensmitteldaten!W:W) * $B18) / 100 / 1000, 0) -> 0 | X45: =IFERROR((_xlfn.XLOOKUP($C45, Lebensmitteldaten!$C:$C, Lebensmitteldaten!X:X) * $B18) / 100 / 1000, 0) -> 0 | Y45: =IFERROR((_xlfn.XLOOKUP($C45, Lebensmitteldaten!$C:$C, Lebensmitteldaten!Y:Y) * $B18) / 100, 0) -> 0 | Z45: =IFERROR((_xlfn.XLOOKUP($C45, Lebensmitteldaten!$C:$C, Lebensmitteldaten!Z:Z) * $B18) / 100, 0) -> 0 | AA45: =IFERROR((_xlfn.XLOOKUP($C45, Lebensmitteldaten!$C:$C, Lebensmitteldaten!AA:AA) * $B18) / 100, 0) -> 0 | AB45: =IFERROR((_xlfn.XLOOKUP($C45, Lebensmitteldaten!$C:$C, Lebensmitteldaten!AB:AB) * $B18) / 100, 0) -> 43.5 | AC45: =IFERROR((_xlfn.XLOOKUP($C45, Lebensmitteldaten!$C:$C, Lebensmitteldaten!AC:AC) * $B18) / 100, 0) -> 0 | AD45: =IFERROR((_xlfn.XLOOKUP($C45, Lebensmitteldaten!$C:$C, Lebensmitteldaten!AD:AD) * $B18) / 100 * 1000, 0) -> 0 | AE45: =IFERROR((_xlfn.XLOOKUP($C45, Lebensmitteldaten!$C:$C, Lebensmitteldaten!AE:AE) * $B18) / 100 * 1000, 0) -> 0 | AF45: =IFERROR((_xlfn.XLOOKUP($C45, Lebensmitteldaten!$C:$C, Lebensmitteldaten!AF:AF) * $B18) / 100 * 1000, 0) -> 0 | AG45: =IFERROR((_xlfn.XLOOKUP($C45, Lebensmitteldaten!$C:$C, Lebensmitteldaten!AG:AG) * $B18) / 100, 0) -> 0 | AH45: =IFERROR((_xlfn.XLOOKUP($C45, Lebensmitteldaten!$C:$C, Lebensmitteldaten!AH:AH) * $B18) / 100, 0) -> 0 | AI45: =IFERROR((_xlfn.XLOOKUP($C45, Lebensmitteldaten!$C:$C, Lebensmitteldaten!AI:AI) * $B18) / 100, 0) -> 0 | AJ45: =IFERROR((_xlfn.XLOOKUP($C45, Lebensmitteldaten!$C:$C, Lebensmitteldaten!AJ:AJ) * $B18) / 100, 0) -> 0 | AK45: =IFERROR((_xlfn.XLOOKUP($C45, Lebensmitteldaten!$C:$C, Lebensmitteldaten!AK:AK) * $B18) / 100, 0) -> 0 | AL45: =IFERROR((_xlfn.XLOOKUP($C45, Lebensmitteldaten!$C:$C, Lebensmitteldaten!AL:AL) * $B18) / 100, 0) -> 0 | AM45: =IFERROR((_xlfn.XLOOKUP($C45, Lebensmitteldaten!$C:$C, Lebensmitteldaten!AM:AM) * $B18) / 100, 0) -> 0 | AN45: =IFERROR((_xlfn.XLOOKUP($C45, Lebensmitteldaten!$C:$C, Lebensmitteldaten!AN:AN) * $B18) / 100 * 1000, 0) -> 0 | AO45: =IFERROR((_xlfn.XLOOKUP($C45, Lebensmitteldaten!$C:$C, Lebensmitteldaten!AO:AO) * $B18) / 100 * 1000, 0) -> 1110 | AP45: =IFERROR((_xlfn.XLOOKUP($C45, Lebensmitteldaten!$C:$C, Lebensmitteldaten!AP:AP) * $B18) / 100 * 1000, 0) -> 828 | AQ45: =IFERROR((_xlfn.XLOOKUP($C45, Lebensmitteldaten!$C:$C, Lebensmitteldaten!AQ:AQ) * $B18) / 100 * 1000, 0) -> 0 | AR45: =IFERROR((_xlfn.XLOOKUP($C45, Lebensmitteldaten!$C:$C, Lebensmitteldaten!AR:AR) * $B18) / 100 * 1000, 0) -> 102 | AS45: =IFERROR((_xlfn.XLOOKUP($C45, Lebensmitteldaten!$C:$C, Lebensmitteldaten!AS:AS) * $B18) / 100 * 1000, 0) -> 0 | AT45: =IFERROR((_xlfn.XLOOKUP($C45, Lebensmitteldaten!$C:$C, Lebensmitteldaten!AT:AT) * $B18) / 100 * 1000, 0) -> 0 | AU45: =IFERROR((_xlfn.XLOOKUP($C45, Lebensmitteldaten!$C:$C, Lebensmitteldaten!AU:AU) * $B18) / 100 * 1000, 0) -> 0 | AV45: =IFERROR((_xlfn.XLOOKUP($C45, Lebensmitteldaten!$C:$C, Lebensmitteldaten!AV:AV) * $B18) / 100 * 1000, 0) -> 0 | AW45: =IFERROR((_xlfn.XLOOKUP($C45, Lebensmitteldaten!$C:$C, Lebensmitteldaten!AW:AW) * $B18) / 100 * 1000, 0) -> 0 | AX45: =IFERROR((_xlfn.XLOOKUP($C45, Lebensmitteldaten!$C:$C, Lebensmitteldaten!AX:AX) * $B18) / 100, 0) -> 0 | AY45: =IFERROR((_xlfn.XLOOKUP($C45, Lebensmitteldaten!$C:$C, Lebensmitteldaten!AY:AY) * $B18) / 100, 0) -> 0 | AZ45: =IFERROR((_xlfn.XLOOKUP($C45, Lebensmitteldaten!$C:$C, Lebensmitteldaten!AZ:AZ) * $B18) / 100, 0) -> 64.815
A46: =_xlfn.XLOOKUP($A19, Lebensmitteldaten!$C:$C, Lebensmitteldaten!$A:$A, "") -> Fette | B46: =_xlfn.XLOOKUP($A19, Lebensmitteldaten!$C:$C, Lebensmitteldaten!$B:$B, "") -> Q170000 | C46: =A19 -> Hanföl | D46: =IFERROR((_xlfn.XLOOKUP($C46, Lebensmitteldaten!$C:$C, Lebensmitteldaten!D:D) * $B19) / 100, 0) -> 54 | E46: =IFERROR((_xlfn.XLOOKUP($C46, Lebensmitteldaten!$C:$C, Lebensmitteldaten!E:E) * $B19) / 100, 0) -> 0.22594142 | F46: =IFERROR((_xlfn.XLOOKUP($C46, Lebensmitteldaten!$C:$C, Lebensmitteldaten!F:F) * $B19) / 100, 0) -> 0 | G46: =IFERROR((_xlfn.XLOOKUP($C46, Lebensmitteldaten!$C:$C, Lebensmitteldaten!G:G) * $B19) / 100, 0) -> 0 | H46: =IFERROR((_xlfn.XLOOKUP($C46, Lebensmitteldaten!$C:$C, Lebensmitteldaten!H:H) * $B19) / 100, 0) -> 6 | I46: =IFERROR((_xlfn.XLOOKUP($C46, Lebensmitteldaten!$C:$C, Lebensmitteldaten!I:I) * $B19) / 100, 0) -> 0 | J46: =IFERROR((_xlfn.XLOOKUP($C46, Lebensmitteldaten!$C:$C, Lebensmitteldaten!J:J) * $B19) / 100, 0) -> 0 | K46: =IFERROR((_xlfn.XLOOKUP($C46, Lebensmitteldaten!$C:$C, Lebensmitteldaten!K:K) * $B19) / 100, 0) -> 0 | L46: =IFERROR((_xlfn.XLOOKUP($C46, Lebensmitteldaten!$C:$C, Lebensmitteldaten!L:L) * $B19) / 100, 0) -> 0 | M46: =IFERROR((_xlfn.XLOOKUP($C46, Lebensmitteldaten!$C:$C, Lebensmitteldaten!M:M) * $B19) / 100, 0) -> 6 | N46: =IFERROR((_xlfn.XLOOKUP($C46, Lebensmitteldaten!$C:$C, Lebensmitteldaten!N:N) * $B19) / 100, 0) -> 0.02650206 | O46: =IFERROR((_xlfn.XLOOKUP($C46, Lebensmitteldaten!$C:$C, Lebensmitteldaten!O:O) * $B19) / 100, 0) -> 0.10212 | P46: =IFERROR((_xlfn.XLOOKUP($C46, Lebensmitteldaten!$C:$C, Lebensmitteldaten!P:P) * $B19) / 100, 0) -> 0.02672826 | Q46: =IFERROR((_xlfn.XLOOKUP($C46, Lebensmitteldaten!$C:$C, Lebensmitteldaten!Q:Q) * $B19) / 100, 0) -> 0.099 | R46: =IFERROR((_xlfn.XLOOKUP($C46, Lebensmitteldaten!$C:$C, Lebensmitteldaten!R:R) * $B19) / 100, 0) -> 0.0406809 | S46: =IFERROR((_xlfn.XLOOKUP($C46, Lebensmitteldaten!$C:$C, Lebensmitteldaten!S:S) * $B19) / 100, 0) -> 0 | T46: =IFERROR((_xlfn.XLOOKUP($C46, Lebensmitteldaten!$C:$C, Lebensmitteldaten!T:T) * $B19) / 100, 0) -> 0.00693432 | U46: =IFERROR((_xlfn.XLOOKUP($C46, Lebensmitteldaten!$C:$C, Lebensmitteldaten!U:U) * $B19) / 100, 0) -> 0.002406588 | V46: =IFERROR((_xlfn.XLOOKUP($C46, Lebensmitteldaten!$C:$C, Lebensmitteldaten!V:V) * $B19) / 100, 0) -> 0 | W46: =IFERROR((_xlfn.XLOOKUP($C46, Lebensmitteldaten!$C:$C, Lebensmitteldaten!W:W) * $B19) / 100 / 1000, 0) -> 0.00014994 | X46: =IFERROR((_xlfn.XLOOKUP($C46, Lebensmitteldaten!$C:$C, Lebensmitteldaten!X:X) * $B19) / 100 / 1000, 0) -> 8.184e-05 | Y46: =IFERROR((_xlfn.XLOOKUP($C46, Lebensmitteldaten!$C:$C, Lebensmitteldaten!Y:Y) * $B19) / 100, 0) -> 0.0006 | Z46: =IFERROR((_xlfn.XLOOKUP($C46, Lebensmitteldaten!$C:$C, Lebensmitteldaten!Z:Z) * $B19) / 100, 0) -> 0 | AA46: =IFERROR((_xlfn.XLOOKUP($C46, Lebensmitteldaten!$C:$C, Lebensmitteldaten!AA:AA) * $B19) / 100, 0) -> 0 | AB46: =IFERROR((_xlfn.XLOOKUP($C46, Lebensmitteldaten!$C:$C, Lebensmitteldaten!AB:AB) * $B19) / 100, 0) -> 0.348 | AC46: =IFERROR((_xlfn.XLOOKUP($C46, Lebensmitteldaten!$C:$C, Lebensmitteldaten!AC:AC) * $B19) / 100, 0) -> 1.26 | AD46: =IFERROR((_xlfn.XLOOKUP($C46, Lebensmitteldaten!$C:$C, Lebensmitteldaten!AD:AD) * $B19) / 100 * 1000, 0) -> 0 | AE46: =IFERROR((_xlfn.XLOOKUP($C46, Lebensmitteldaten!$C:$C, Lebensmitteldaten!AE:AE) * $B19) / 100 * 1000, 0) -> 0 | AF46: =IFERROR((_xlfn.XLOOKUP($C46, Lebensmitteldaten!$C:$C, Lebensmitteldaten!AF:AF) * $B19) / 100 * 1000, 0) -> 0 | AG46: =IFERROR((_xlfn.XLOOKUP($C46, Lebensmitteldaten!$C:$C, Lebensmitteldaten!AG:AG) * $B19) / 100, 0) -> 0 | AH46: =IFERROR((_xlfn.XLOOKUP($C46, Lebensmitteldaten!$C:$C, Lebensmitteldaten!AH:AH) * $B19) / 100, 0) -> 0 | AI46: =IFERROR((_xlfn.XLOOKUP($C46, Lebensmitteldaten!$C:$C, Lebensmitteldaten!AI:AI) * $B19) / 100, 0) -> 0 | AJ46: =IFERROR((_xlfn.XLOOKUP($C46, Lebensmitteldaten!$C:$C, Lebensmitteldaten!AJ:AJ) * $B19) / 100, 0) -> 7.26 | AK46: =IFERROR((_xlfn.XLOOKUP($C46, Lebensmitteldaten!$C:$C, Lebensmitteldaten!AK:AK) * $B19) / 100, 0) -> 0 | AL46: =IFERROR((_xlfn.XLOOKUP($C46, Lebensmitteldaten!$C:$C, Lebensmitteldaten!AL:AL) * $B19) / 100, 0) -> 0 | AM46: =IFERROR((_xlfn.XLOOKUP($C46, Lebensmitteldaten!$C:$C, Lebensmitteldaten!AM:AM) * $B19) / 100, 0) -> 0 | AN46: =IFERROR((_xlfn.XLOOKUP($C46, Lebensmitteldaten!$C:$C, Lebensmitteldaten!AN:AN) * $B19) / 100 * 1000, 0) -> 1128 | AO46: =IFERROR((_xlfn.XLOOKUP($C46, Lebensmitteldaten!$C:$C, Lebensmitteldaten!AO:AO) * $B19) / 100 * 1000, 0) -> 0 | AP46: =IFERROR((_xlfn.XLOOKUP($C46, Lebensmitteldaten!$C:$C, Lebensmitteldaten!AP:AP) * $B19) / 100 * 1000, 0) -> 0 | AQ46: =IFERROR((_xlfn.XLOOKUP($C46, Lebensmitteldaten!$C:$C, Lebensmitteldaten!AQ:AQ) * $B19) / 100 * 1000, 0) -> 3156 | AR46: =IFERROR((_xlfn.XLOOKUP($C46, Lebensmitteldaten!$C:$C, Lebensmitteldaten!AR:AR) * $B19) / 100 * 1000, 0) -> 3156 | AS46: =IFERROR((_xlfn.XLOOKUP($C46, Lebensmitteldaten!$C:$C, Lebensmitteldaten!AS:AS) * $B19) / 100 * 1000, 0) -> 0 | AT46: =IFERROR((_xlfn.XLOOKUP($C46, Lebensmitteldaten!$C:$C, Lebensmitteldaten!AT:AT) * $B19) / 100 * 1000, 0) -> 0 | AU46: =IFERROR((_xlfn.XLOOKUP($C46, Lebensmitteldaten!$C:$C, Lebensmitteldaten!AU:AU) * $B19) / 100 * 1000, 0) -> 0 | AV46: =IFERROR((_xlfn.XLOOKUP($C46, Lebensmitteldaten!$C:$C, Lebensmitteldaten!AV:AV) * $B19) / 100 * 1000, 0) -> 0 | AW46: =IFERROR((_xlfn.XLOOKUP($C46, Lebensmitteldaten!$C:$C, Lebensmitteldaten!AW:AW) * $B19) / 100 * 1000, 0) -> 0 | AX46: =IFERROR((_xlfn.XLOOKUP($C46, Lebensmitteldaten!$C:$C, Lebensmitteldaten!AX:AX) * $B19) / 100, 0) -> 0 | AY46: =IFERROR((_xlfn.XLOOKUP($C46, Lebensmitteldaten!$C:$C, Lebensmitteldaten!AY:AY) * $B19) / 100, 0) -> 4.1958 | AZ46: =IFERROR((_xlfn.XLOOKUP($C46, Lebensmitteldaten!$C:$C, Lebensmitteldaten!AZ:AZ) * $B19) / 100, 0) -> 0.51852
A47: =_xlfn.XLOOKUP($A20, Lebensmitteldaten!$C:$C, Lebensmitteldaten!$A:$A, "") -> Gemüse | B47: =_xlfn.XLOOKUP($A20, Lebensmitteldaten!$C:$C, Lebensmitteldaten!$B:$B, "") -> G581032 | C47: =A20 -> Kürbis Hokkaido (C. maxima) gekocht | D47: =IFERROR((_xlfn.XLOOKUP($C47, Lebensmitteldaten!$C:$C, Lebensmitteldaten!D:D) * $B20) / 100, 0) -> 9 | E47: =IFERROR((_xlfn.XLOOKUP($C47, Lebensmitteldaten!$C:$C, Lebensmitteldaten!E:E) * $B20) / 100, 0) -> 0.037656904 | F47: =IFERROR((_xlfn.XLOOKUP($C47, Lebensmitteldaten!$C:$C, Lebensmitteldaten!F:F) * $B20) / 100, 0) -> 0.42 | G47: =IFERROR((_xlfn.XLOOKUP($C47, Lebensmitteldaten!$C:$C, Lebensmitteldaten!G:G) * $B20) / 100, 0) -> 0.357 | H47: =IFERROR((_xlfn.XLOOKUP($C47, Lebensmitteldaten!$C:$C, Lebensmitteldaten!H:H) * $B20) / 100, 0) -> 0.06 | I47: =IFERROR((_xlfn.XLOOKUP($C47, Lebensmitteldaten!$C:$C, Lebensmitteldaten!I:I) * $B20) / 100, 0) -> 3.8784 | J47: =IFERROR((_xlfn.XLOOKUP($C47, Lebensmitteldaten!$C:$C, Lebensmitteldaten!J:J) * $B20) / 100, 0) -> 0 | K47: =IFERROR((_xlfn.XLOOKUP($C47, Lebensmitteldaten!$C:$C, Lebensmitteldaten!K:K) * $B20) / 100, 0) -> 0.228 | L47: =IFERROR((_xlfn.XLOOKUP($C47, Lebensmitteldaten!$C:$C, Lebensmitteldaten!L:L) * $B20) / 100, 0) -> 25.4136 | M47: =IFERROR((_xlfn.XLOOKUP($C47, Lebensmitteldaten!$C:$C, Lebensmitteldaten!M:M) * $B20) / 100, 0) -> 4.5864 | N47: =IFERROR((_xlfn.XLOOKUP($C47, Lebensmitteldaten!$C:$C, Lebensmitteldaten!N:N) * $B20) / 100, 0) -> 10.02 | O47: =IFERROR((_xlfn.XLOOKUP($C47, Lebensmitteldaten!$C:$C, Lebensmitteldaten!O:O) * $B20) / 100, 0) -> 11.19 | P47: =IFERROR((_xlfn.XLOOKUP($C47, Lebensmitteldaten!$C:$C, Lebensmitteldaten!P:P) * $B20) / 100, 0) -> 3.39 | Q47: =IFERROR((_xlfn.XLOOKUP($C47, Lebensmitteldaten!$C:$C, Lebensmitteldaten!Q:Q) * $B20) / 100, 0) -> 1.8 | R47: =IFERROR((_xlfn.XLOOKUP($C47, Lebensmitteldaten!$C:$C, Lebensmitteldaten!R:R) * $B20) / 100, 0) -> 67.8 | S47: =IFERROR((_xlfn.XLOOKUP($C47, Lebensmitteldaten!$C:$C, Lebensmitteldaten!S:S) * $B20) / 100, 0) -> 0 | T47: =IFERROR((_xlfn.XLOOKUP($C47, Lebensmitteldaten!$C:$C, Lebensmitteldaten!T:T) * $B20) / 100, 0) -> 0.1221 | U47: =IFERROR((_xlfn.XLOOKUP($C47, Lebensmitteldaten!$C:$C, Lebensmitteldaten!U:U) * $B20) / 100, 0) -> 0.069 | V47: =IFERROR((_xlfn.XLOOKUP($C47, Lebensmitteldaten!$C:$C, Lebensmitteldaten!V:V) * $B20) / 100, 0) -> 0 | W47: =IFERROR((_xlfn.XLOOKUP($C47, Lebensmitteldaten!$C:$C, Lebensmitteldaten!W:W) * $B20) / 100 / 1000, 0) -> 0.01473 | X47: =IFERROR((_xlfn.XLOOKUP($C47, Lebensmitteldaten!$C:$C, Lebensmitteldaten!X:X) * $B20) / 100 / 1000, 0) -> 0.01482 | Y47: =IFERROR((_xlfn.XLOOKUP($C47, Lebensmitteldaten!$C:$C, Lebensmitteldaten!Y:Y) * $B20) / 100, 0) -> 0.39 | Z47: =IFERROR((_xlfn.XLOOKUP($C47, Lebensmitteldaten!$C:$C, Lebensmitteldaten!Z:Z) * $B20) / 100, 0) -> 0 | AA47: =IFERROR((_xlfn.XLOOKUP($C47, Lebensmitteldaten!$C:$C, Lebensmitteldaten!AA:AA) * $B20) / 100, 0) -> 0 | AB47: =IFERROR((_xlfn.XLOOKUP($C47, Lebensmitteldaten!$C:$C, Lebensmitteldaten!AB:AB) * $B20) / 100, 0) -> 0.3333 | AC47: =IFERROR((_xlfn.XLOOKUP($C47, Lebensmitteldaten!$C:$C, Lebensmitteldaten!AC:AC) * $B20) / 100, 0) -> 29.7 | AD47: =IFERROR((_xlfn.XLOOKUP($C47, Lebensmitteldaten!$C:$C, Lebensmitteldaten!AD:AD) * $B20) / 100 * 1000, 0) -> 19.5 | AE47: =IFERROR((_xlfn.XLOOKUP($C47, Lebensmitteldaten!$C:$C, Lebensmitteldaten!AE:AE) * $B20) / 100 * 1000, 0) -> 12.9 | AF47: =IFERROR((_xlfn.XLOOKUP($C47, Lebensmitteldaten!$C:$C, Lebensmitteldaten!AF:AF) * $B20) / 100 * 1000, 0) -> 346.8 | AG47: =IFERROR((_xlfn.XLOOKUP($C47, Lebensmitteldaten!$C:$C, Lebensmitteldaten!AG:AG) * $B20) / 100, 0) -> 23.7 | AH47: =IFERROR((_xlfn.XLOOKUP($C47, Lebensmitteldaten!$C:$C, Lebensmitteldaten!AH:AH) * $B20) / 100, 0) -> 0 | AI47: =IFERROR((_xlfn.XLOOKUP($C47, Lebensmitteldaten!$C:$C, Lebensmitteldaten!AI:AI) * $B20) / 100, 0) -> 3.0333 | AJ47: =IFERROR((_xlfn.XLOOKUP($C47, Lebensmitteldaten!$C:$C, Lebensmitteldaten!AJ:AJ) * $B20) / 100, 0) -> 1.2 | AK47: =IFERROR((_xlfn.XLOOKUP($C47, Lebensmitteldaten!$C:$C, Lebensmitteldaten!AK:AK) * $B20) / 100, 0) -> 3.9 | AL47: =IFERROR((_xlfn.XLOOKUP($C47, Lebensmitteldaten!$C:$C, Lebensmitteldaten!AL:AL) * $B20) / 100, 0) -> 0.09 | AM47: =IFERROR((_xlfn.XLOOKUP($C47, Lebensmitteldaten!$C:$C, Lebensmitteldaten!AM:AM) * $B20) / 100, 0) -> 0 | AN47: =IFERROR((_xlfn.XLOOKUP($C47, Lebensmitteldaten!$C:$C, Lebensmitteldaten!AN:AN) * $B20) / 100 * 1000, 0) -> 18.3 | AO47: =IFERROR((_xlfn.XLOOKUP($C47, Lebensmitteldaten!$C:$C, Lebensmitteldaten!AO:AO) * $B20) / 100 * 1000, 0) -> 0 | AP47: =IFERROR((_xlfn.XLOOKUP($C47, Lebensmitteldaten!$C:$C, Lebensmitteldaten!AP:AP) * $B20) / 100 * 1000, 0) -> 0 | AQ47: =IFERROR((_xlfn.XLOOKUP($C47, Lebensmitteldaten!$C:$C, Lebensmitteldaten!AQ:AQ) * $B20) / 100 * 1000, 0) -> 10.8 | AR47: =IFERROR((_xlfn.XLOOKUP($C47, Lebensmitteldaten!$C:$C, Lebensmitteldaten!AR:AR) * $B20) / 100 * 1000, 0) -> 10.8 | AS47: =IFERROR((_xlfn.XLOOKUP($C47, Lebensmitteldaten!$C:$C, Lebensmitteldaten!AS:AS) * $B20) / 100 * 1000, 0) -> 14.4 | AT47: =IFERROR((_xlfn.XLOOKUP($C47, Lebensmitteldaten!$C:$C, Lebensmitteldaten!AT:AT) * $B20) / 100 * 1000, 0) -> 0.9 | AU47: =IFERROR((_xlfn.XLOOKUP($C47, Lebensmitteldaten!$C:$C, Lebensmitteldaten!AU:AU) * $B20) / 100 * 1000, 0) -> 7.5 | AV47: =IFERROR((_xlfn.XLOOKUP($C47, Lebensmitteldaten!$C:$C, Lebensmitteldaten!AV:AV) * $B20) / 100 * 1000, 0) -> 15 | AW47: =IFERROR((_xlfn.XLOOKUP($C47, Lebensmitteldaten!$C:$C, Lebensmitteldaten!AW:AW) * $B20) / 100 * 1000, 0) -> 6 | AX47: =IFERROR((_xlfn.XLOOKUP($C47, Lebensmitteldaten!$C:$C, Lebensmitteldaten!AX:AX) * $B20) / 100, 0) -> 0 | AY47: =IFERROR((_xlfn.XLOOKUP($C47, Lebensmitteldaten!$C:$C, Lebensmitteldaten!AY:AY) * $B20) / 100, 0) -> 98.901 | AZ47: =IFERROR((_xlfn.XLOOKUP($C47, Lebensmitteldaten!$C:$C, Lebensmitteldaten!AZ:AZ) * $B20) / 100, 0) -> 0.496617
